Workbook

Sheet Client Dashboard
G1: MAHON PERFORMANCE
B2: NAME | E2: Becky Marlow | O2: COACH'S NOTES
B3: AGE (yrs)
B4: HEIGHT (cm)
B5: START WEIGHT (kg) | E5: 66.5 | H5: TARGETS
B6: CURRENT WEIGHT (kg) | E6: {=IFERROR(INDEX('BW Tracker'!Y:Y,MATCH(143^143,'BW Tracker'!Y:Y)),"")} -> 61.2 | H6: DAY | J6: TD | L6: NTD
H7: CALS | J7: 1050 | L7: 1050
B8: START DATE | E8: 45698 | H8: PRO | J8: 120 | L8: 120
B9: CURRENT WEEK | E9: =IF(ISBLANK(E8),"",ROUNDUP((TODAY()-E8)/7,0)) -> 37 | H9: CHO
B10: OVERARCHING GOAL | E10: Health | H10: FAT
B11: GOAL DATE | H11: CARDIO | J11: 20min PWO
B12: WEEKS UNTIL GOAL | E12: =IF(ISBLANK(E11),"",IF(TRUNC((E11-TODAY())/7)=0,"",IF(TRUNC((E11-TODAY())/7)=1,TRUNC((E11-TODAY())/7)&" week ",TRUNC((E11-TODAY())/7)&" weeks ")))&IF(ISBLANK(E11),"",IF(((E11-TODAY())-(TRUNC((E11-TODAY())/7)*7))=0,"",IF(((E11-TODAY())-(TRUNC((E11-TODAY())/7)*7))=1,((E11-TODAY())-(TRUNC((E11-TODAY())/7)*7))&" day",((E11-TODAY())-(TRUNC((E11-TODAY())/7)*7))&" days"))) | H12: STEPS | J12: 10000
B14: SHORT TERM GOALS - List 3 things you want to achieve in the next 3-6 MONTHS.
B15: 1
B16: 2
B17: 3
B19: LONG TERM GOALS - List 3 things you want to achieve in the next 12 MONTHS.
B20: 1
B21: 2
B22: 3

Sheet Daily Tracker
E1: MAHON PERFORMANCE | X1: 1 | Y1: CLICK HERE | Z1: CLICK HERE
X2: 2 | Y2: CLICK HERE | Z2: CLICK HERE
B3: NAME | C3: ='Client Dashboard'!E2 -> Becky Marlow | X3: 3 | Y3: CLICK HERE | Z3: CLICK HERE
B4: WEEK | C4: =IF(ISBLANK(C9),"",ROUNDUP((TODAY()-C9)/7,0)) -> 37 | D4: CLICK HERE | X4: 4 | Y4: CLICK HERE | Z4: CLICK HERE
X5: 5 | Y5: CLICK HERE | Z5: CLICK HERE
X6: 6 | Y6: CLICK HERE | Z6: CLICK HERE
B7: WEEK NO. | C7: DATE | D7: BODYWEIGHT (kg) | E7: MENSTRUAL CYCLE | F7: MENSTRUAL CYCLE Day // Symptoms | H7: NUTRITION | I7: CALORIES (kcals) | J7: PRO (g) | K7: CHO (g) | L7: FAT (g) | M7: ACTIVITY | N7: STEPS | O7: CARDIO (mins) | P7: RESISTANCE TRAINING Which session? | X7: 7 | Y7: CLICK HERE | Z7: CLICK HERE
B8: 1 | C8: NOTES | D8: Weigh-in fasted | F8: Enter 1 when you start your period | I8: See dashboard or nutrition tabs for targets. | X8: 8 | Y8: CLICK HERE | Z8: CLICK HERE
C9: 45698 | I9: =J9*4+K9*4+L9*9 -> 0 | X9: 9 | Y9: CLICK HERE | Z9: CLICK HERE
C10: =IF(ISBLANK($C$9),"",C9+1) -> 45699 | F10: =IF(ISNUMBER(F9),F9+1,"") | I10: =J10*4+K10*4+L10*9 -> 0 | X10: 10 | Y10: CLICK HERE | Z10: CLICK HERE
C11: =IF(ISBLANK($C$9),"",C10+1) -> 45700 | F11: =IF(ISNUMBER(F10),F10+1,"") | I11: 1405 | J11: 111 | N11: 8000 | X11: 11 | Y11: CLICK HERE | Z11: CLICK HERE
C12: =IF(ISBLANK($C$9),"",C11+1) -> 45701 | F12: =IF(ISNUMBER(F11),F11+1,"") | I12: 1305 | J12: 110 | N12: 7863 | O12: 20 | P12: Lower | X12: 12 | Y12: CLICK HERE | Z12: CLICK HERE
C13: =IF(ISBLANK($C$9),"",C12+1) -> 45702 | F13: =IF(ISNUMBER(F12),F12+1,"") | I13: 1447 | J13: 100 | N13: 8560 | O13: 20 | P13: Lower | X13: 13 | Y13: CLICK HERE | Z13: CLICK HERE
C14: =IF(ISBLANK($C$9),"",C13+1) -> 45703 | F14: =IF(ISNUMBER(F13),F13+1,"") | G14: 1 | I14: 1496 | J14: 116 | N14: 7897 | P14: Pilates | X14: 14 | Y14: CLICK HERE | Z14: CLICK HERE
C15: =IF(ISBLANK($C$9),"",C14+1) -> 45704 | D15: 65.15 | F15: =IF(ISNUMBER(F14),F14+1,"") | I15: 1490 | J15: 115 | N15: 9206 | O15: 20 | P15: Upper | X15: 15 | Y15: CLICK HERE | Z15: CLICK HERE
C16: AVERAGES | D16: =IFERROR(ROUND(AVERAGE(D9:D15),1),0) -> 65.2 | F16: Also list any PMS symptoms | I16: =IFERROR(ROUND(AVERAGEIF(I9:I15,"<>0"),0),0) -> 1429 | J16: =IFERROR(ROUND(AVERAGE(J9:J15),0),0) -> 110 | K16: =IFERROR(ROUND(AVERAGE(K9:K15),0),0) -> 0 | L16: =IFERROR(ROUND(AVERAGE(L9:L15),0),0) -> 0 | N16: =IFERROR(ROUND(AVERAGE(N9:N15),0),0) -> 8305 | O16: =IFERROR(SUM(O9:O15),0) -> 60 | P16: =IFERROR(COUNTA(P9:P15),0) -> 4 | X16: 16 | Y16: CLICK HERE | Z16: CLICK HERE
X17: 17 | Y17: CLICK HERE | Z17: CLICK HERE
B18: WEEK NO. | C18: DATE | D18: BODYWEIGHT (kg) | E18: MENSTRUAL CYCLE | F18: MENSTRUAL CYCLE Day // Symptoms | H18: NUTRITION | I18: CALORIES (kcals) | J18: PRO (g) | K18: CHO (g) | L18: FAT (g) | M18: ACTIVITY | N18: STEPS | O18: CARDIO (mins) | P18: RESISTANCE TRAINING Which session? | X18: 18 | Y18: CLICK HERE | Z18: CLICK HERE
B19: =B8+1 -> 2 | C19: NOTES | D19: Weigh-in fasted | F19: Enter 1 when you start your period | I19: See dashboard or nutrition tabs for targets. | X19: 19 | Y19: CLICK HERE | Z19: CLICK HERE
C20: =IF(ISBLANK($C$9),"",C15+1) -> 45705 | D20: 64.85 | F20: =IF(ISNUMBER(F15),F15+1,"") | I20: =J20*4+K20*4+L20*9 -> 0 | X20: 20 | Y20: CLICK HERE | Z20: CLICK HERE
C21: =IF(ISBLANK($C$9),"",C20+1) -> 45706 | F21: =IF(ISNUMBER(F20),F20+1,"") | I21: 1200 | J21: 115 | N21: 8976 | O21: 20 | P21: Lower | X21: 21 | Y21: CLICK HERE | Z21: CLICK HERE
C22: =IF(ISBLANK($C$9),"",C21+1) -> 45707 | D22: 64.6 | F22: =IF(ISNUMBER(F21),F21+1,"") | I22: 1234 | J22: 106 | N22: 9650 | X22: 22 | Y22: CLICK HERE | Z22: CLICK HERE
C23: =IF(ISBLANK($C$9),"",C22+1) -> 45708 | D23: 64.5 | F23: =IF(ISNUMBER(F22),F22+1,"") | I23: 1200 | J23: 130 | N23: 8574 | O23: 30 | P23: Upper | X23: 23 | Y23: CLICK HERE | Z23: CLICK HERE
C24: =IF(ISBLANK($C$9),"",C23+1) -> 45709 | F24: =IF(ISNUMBER(F23),F23+1,"") | I24: 1275 | J24: 112 | N24: 9875 | O24: 20 | P24: Lower | X24: 24 | Y24: CLICK HERE | Z24: CLICK HERE
C25: =IF(ISBLANK($C$9),"",C24+1) -> 45710 | F25: =IF(ISNUMBER(F24),F24+1,"") | I25: 1303 | J25: 108 | N25: 11086 | O25: 20 | P25: Lower | X25: 25 | Y25: CLICK HERE | Z25: CLICK HERE
C26: =IF(ISBLANK($C$9),"",C25+1) -> 45711 | D26: 64.5 | F26: =IF(ISNUMBER(F25),F25+1,"") | I26: =J26*4+K26*4+L26*9 -> 0 | X26: 26 | Y26: CLICK HERE | Z26: CLICK HERE
C27: AVERAGES | D27: =IFERROR(ROUND(AVERAGE(D20:D26),1),0) -> 64.6 | F27: Also list any PMS symptoms | I27: =IFERROR(ROUND(AVERAGEIF(I20:I26,"<>0"),0),0) -> 1242 | J27: =IFERROR(ROUND(AVERAGE(J20:J26),0),0) -> 114 | K27: =IFERROR(ROUND(AVERAGE(K20:K26),0),0) -> 0 | L27: =IFERROR(ROUND(AVERAGE(L20:L26),0),0) -> 0 | N27: =IFERROR(ROUND(AVERAGE(N20:N26),0),0) -> 9632 | O27: =IFERROR(SUM(O20:O26),0) -> 90 | P27: =IFERROR(COUNTA(P20:P26),0) -> 4 | X27: 27 | Y27: CLICK HERE | Z27: CLICK HERE
X28: 28 | Y28: CLICK HERE | Z28: CLICK HERE
B29: WEEK NO. | C29: DATE | D29: BODYWEIGHT (kg) | E29: MENSTRUAL CYCLE | F29: MENSTRUAL CYCLE Day // Symptoms | H29: NUTRITION | I29: CALORIES (kcals) | J29: PRO (g) | K29: CHO (g) | L29: FAT (g) | M29: ACTIVITY | N29: STEPS | O29: CARDIO (mins) | P29: RESISTANCE TRAINING Which session? | X29: 29 | Y29: CLICK HERE | Z29: CLICK HERE
B30: =B19+1 -> 3 | C30: NOTES | D30: Weigh-in fasted | F30: Enter 1 when you start your period | I30: See dashboard or nutrition tabs for targets. | X30: 30 | Y30: CLICK HERE | Z30: CLICK HERE
C31: =IF(ISBLANK($C$9),"",C26+1) -> 45712 | D31: 63.5 | F31: =IF(ISNUMBER(F26),F26+1,"") | I31: 1150 | J31: 115 | N31: 8057 | O31: 20 | P31: Lower | X31: 31 | Y31: CLICK HERE | Z31: CLICK HERE
C32: =IF(ISBLANK($C$9),"",C31+1) -> 45713 | F32: =IF(ISNUMBER(F31),F31+1,"") | I32: 1013 | J32: 109 | X32: 32 | Y32: CLICK HERE | Z32: CLICK HERE
C33: =IF(ISBLANK($C$9),"",C32+1) -> 45714 | F33: =IF(ISNUMBER(F32),F32+1,"") | I33: 886 | J33: 119 | N33: 9764 | O33: 20 | P33: Lower | X33: 33 | Y33: CLICK HERE | Z33: CLICK HERE
C34: =IF(ISBLANK($C$9),"",C33+1) -> 45715 | F34: =IF(ISNUMBER(F33),F33+1,"") | I34: 996 | J34: 119 | N34: 8596 | O34: 20 | P34: Upper | X34: 34 | Y34: CLICK HERE | Z34: CLICK HERE
C35: =IF(ISBLANK($C$9),"",C34+1) -> 45716 | F35: =IF(ISNUMBER(F34),F34+1,"") | I35: 1032 | J35: 110 | N35: 8547 | O35: 20 | P35: Lower | X35: 35 | Y35: CLICK HERE | Z35: CLICK HERE
C36: =IF(ISBLANK($C$9),"",C35+1) -> 45717 | F36: =IF(ISNUMBER(F35),F35+1,"") | I36: 1007 | J36: 113 | N36: 11254 | X36: 36 | Y36: CLICK HERE | Z36: CLICK HERE
C37: =IF(ISBLANK($C$9),"",C36+1) -> 45718 | F37: =IF(ISNUMBER(F36),F36+1,"") | I37: 1011 | J37: 98 | N37: 9087 | X37: 37 | Y37: CLICK HERE | Z37: CLICK HERE
C38: AVERAGES | D38: =IFERROR(ROUND(AVERAGE(D31:D37),1),0) -> 63.5 | F38: Also list any PMS symptoms | I38: =IFERROR(ROUND(AVERAGEIF(I31:I37,"<>0"),0),0) -> 1014 | J38: =IFERROR(ROUND(AVERAGE(J31:J37),0),0) -> 112 | K38: =IFERROR(ROUND(AVERAGE(K31:K37),0),0) -> 0 | L38: =IFERROR(ROUND(AVERAGE(L31:L37),0),0) -> 0 | N38: =IFERROR(ROUND(AVERAGE(N31:N37),0),0) -> 9218 | O38: =IFERROR(SUM(O31:O37),0) -> 80 | P38: =IFERROR(COUNTA(P31:P37),0) -> 4 | X38: 38 | Y38: CLICK HERE | Z38: CLICK HERE
X39: 39 | Y39: CLICK HERE | Z39: CLICK HERE
B40: WEEK NO. | C40: DATE | D40: BODYWEIGHT (kg) | E40: MENSTRUAL CYCLE | F40: MENSTRUAL CYCLE Day // Symptoms | H40: NUTRITION | I40: CALORIES (kcals) | J40: PRO (g) | K40: CHO (g) | L40: FAT (g) | M40: ACTIVITY | N40: STEPS | O40: CARDIO (mins) | P40: RESISTANCE TRAINING Which session? | X40: 40 | Y40: CLICK HERE | Z40: CLICK HERE
...

Sheet Check-In
G1: MAHON PERFORMANCE
C3: NAME | D3: ='Client Dashboard'!E2 -> Becky Marlow
C4: WEEK | D4: =IF(ISBLANK('Daily Tracker'!C4),"",'Daily Tracker'!C4) -> 37 | E4: CLICK HERE
C7: QUESTIONS | G7: WEEK 1 | H7: WEEK 2 | I7: WEEK 3 | J7: WEEK 4 | K7: WEEK 5 | L7: WEEK 6 | M7: WEEK 7 | N7: WEEK 8 | O7: WEEK 9 | P7: WEEK 10 | Q7: WEEK 11 | R7: WEEK 12 | S7: WEEK 13 | T7: WEEK 14 | U7: WEEK 15 | V7: WEEK 16 | W7: WEEK 17 | X7: WEEK 18 | Y7: WEEK 19 | Z7: WEEK 20 | AA7: WEEK 21 | AB7: WEEK 22 | AC7: WEEK 23 | AD7: WEEK 24 | AE7: WEEK 25 | AF7: WEEK 26 | AG7: WEEK 27 | AH7: WEEK 28 | AI7: WEEK 29 | AJ7: WEEK 30 | AK7: WEEK 31 | AL7: WEEK 32 | AM7: WEEK 33 | AN7: WEEK 34 | AO7: WEEK 35 | AP7: WEEK 36 | AQ7: WEEK 37 | AR7: WEEK 38 | AS7: WEEK 39 | AT7: WEEK 40 | AU7: WEEK 41 | AV7: WEEK 42 | AW7: WEEK 43 | AX7: WEEK 44 | AY7: WEEK 45 | AZ7: WEEK 46 | BA7: WEEK 47 | BB7: WEEK 48 | BC7: WEEK 49 | BD7: WEEK 50 | BE7: WEEK 51 | BF7: WEEK 52
B8: 1 | C8: Rate your energy levels on a scale of 1-10 and list any relevant details.
B9: 2 | C9: Rate your muscle soreness on a scale of 1-10 and list any relevant details.
B10: 3 | C10: Rate your stress levels on a scale of 1-10 and list any relevant details.
B11: 4 | C11: Rate your mood on a scale of 1-10 and list any relevant details.
B12: 5 | C12: How was your readiness to train/motivation levels?
B13: 6 | C13: How was your strength and performance during training this week?
B14: 7 | C14: Rate your dietary adherence on a scale of 1-10 and list any relevant details.
B15: 8 | C15: Rate your hunger/appetite on a scale of 1-10 and list any relevant details.
B16: 9 | C16: Rate your cravings on a scale of 1-10 and list any relevant details.
B17: 10 | C17: Have you suffered from any digestive stress or bloating? If so, are there any foods that you noticed caused these digestive issues?
B18: 11 | C18: Average hours of sleep per night?
B19: 12 | C19: Average bed time?
... B21: 14 | C21: Rate your sleep quality on a scale of 1-10 and list any relevant details.
C29: Template and Design by Lucia Hughes

Sheet BW Tracker
X1: 1 | Y1: =IF(ISNA(D3),"",D3) -> 65.2
B2: WEEK | C2: DAILY BW MEASUREMENT | D2: WEEKLY AVERAGE | P2: MAHON PERFORMANCE | X2: 2 | Y2: =IF(ISNA(D10),"",D10) -> 64.6
B3: 1 | C3: ='Daily Tracker'!D9 | D3: =IFERROR(ROUND(AVERAGE(C3:C9),1),NA()) -> 65.2 | X3: 3 | Y3: =IF(ISNA(D17),"",D17) -> 63.5
C4: ='Daily Tracker'!D10 | X4: 4 | Y4: =IF(ISNA(D24),"",D24) -> 63
C5: ='Daily Tracker'!D11 | X5: 5 | Y5: =IF(ISNA(D31),"",D31) -> 63.5
C6: ='Daily Tracker'!D12 | X6: 6 | Y6: =IF(ISNA(D38),"",D38) -> 62
C7: ='Daily Tracker'!D13 | X7: 7 | Y7: =IF(ISNA(D45),"",D45) -> 61.2
C8: ='Daily Tracker'!D14 | X8: 8 | Y8: =IF(ISNA(D52),"",D52)
C9: ='Daily Tracker'!D15 -> 65.15 | X9: 9 | Y9: =IF(ISNA(D59),"",D59)
B10: =B3+1 -> 2 | C10: ='Daily Tracker'!D20 -> 64.85 | D10: =IFERROR(ROUND(AVERAGE(C10:C16),1),NA()) -> 64.6 | X10: 10 | Y10: =IF(ISNA(D66),"",D66)
C11: ='Daily Tracker'!D21 | X11: 11 | Y11: =IF(ISNA(D73),"",D73)
C12: ='Daily Tracker'!D22 -> 64.6 | X12: 12 | Y12: =IF(ISNA(D80),"",D80)
C13: ='Daily Tracker'!D23 -> 64.5 | X13: 13 | Y13: =IF(ISNA(D87),"",D87)
C14: ='Daily Tracker'!D24 | X14: 14 | Y14: =IF(ISNA(D94),"",D94)
C15: ='Daily Tracker'!D25 | X15: 15 | Y15: =IF(ISNA(D101),"",D101)
C16: ='Daily Tracker'!D26 -> 64.5 | X16: 16 | Y16: =IF(ISNA(D108),"",D108)
B17: =B10+1 -> 3 | C17: ='Daily Tracker'!D31 -> 63.5 | D17: =IFERROR(ROUND(AVERAGE(C17:C23),1),NA()) -> 63.5 | X17: 17 | Y17: =IF(ISNA(D115),"",D115)
C18: ='Daily Tracker'!D32 | X18: 18 | Y18: =IF(ISNA(D122),"",D122)
C19: ='Daily Tracker'!D33 | X19: 19 | Y19: =IF(ISNA(D129),"",D129)
C20: ='Daily Tracker'!D34 | X20: 20 | Y20: =IF(ISNA(D136),"",D136)
C21: ='Daily Tracker'!D35 | X21: 21 | Y21: =IF(ISNA(D143),"",D143)
C22: ='Daily Tracker'!D36 | X22: 22 | Y22: =IF(ISNA(D150),"",D150)
C23: ='Daily Tracker'!D37 | X23: 23 | Y23: =IF(ISNA(D157),"",D157)
B24: =B17+1 -> 4 | C24: ='Daily Tracker'!D42 -> 63 | D24: =IFERROR(ROUND(AVERAGE(C24:C30),1),NA()) -> 63 | X24: 24 | Y24: =IF(ISNA(D164),"",D164)
C25: ='Daily Tracker'!D43 | X25: 25 | Y25: =IF(ISNA(D171),"",D171)
C26: ='Daily Tracker'!D44 | X26: 26 | Y26: =IF(ISNA(D178),"",D178)
C27: ='Daily Tracker'!D45 | X27: 27 | Y27: =IF(ISNA(D185),"",D185)
C28: ='Daily Tracker'!D46 | X28: 28 | Y28: =IF(ISNA(D192),"",D192)
C29: ='Daily Tracker'!D47 | X29: 29 | Y29: =IF(ISNA(D199),"",D199)
C30: ='Daily Tracker'!D48 | X30: 30 | Y30: =IF(ISNA(D206),"",D206)
B31: =B24+1 -> 5 | C31: ='Daily Tracker'!D53 -> 64 | D31: =IFERROR(ROUND(AVERAGE(C31:C37),1),NA()) -> 63.5 | X31: 31 | Y31: =IF(ISNA(D213),"",D213)
C32: ='Daily Tracker'!D54 | X32: 32 | Y32: =IF(ISNA(D220),"",D220)
C33: ='Daily Tracker'!D55 -> 63.8 | X33: 33 | Y33: =IF(ISNA(D227),"",D227)
C34: ='Daily Tracker'!D56 -> 63.5 | X34: 34 | Y34: =IF(ISNA(D234),"",D234)
C35: ='Daily Tracker'!D57 -> 62.95 | X35: 35 | Y35: =IF(ISNA(D241),"",D241)
C36: ='Daily Tracker'!D58 -> 63.2 | X36: 36 | Y36: =IF(ISNA(D248),"",D248)
C37: ='Daily Tracker'!D59 | X37: 37 | Y37: =IF(ISNA(D255),"",D255)
B38: =B31+1 -> 6 | C38: ='Daily Tracker'!D64 -> 62 | D38: =IFERROR(ROUND(AVERAGE(C38:C44),1),NA()) -> 62 | X38: 38 | Y38: =IF(ISNA(D262),"",D262)
C39: ='Daily Tracker'!D65 | X39: 39 | Y39: =IF(ISNA(D269),"",D269)
C40: ='Daily Tracker'!D66 | X40: 40 | Y40: =IF(ISNA(D276),"",D276)
...

Sheet Measurements
B2: WEEK | C2: WAIST | D2: HIPS | E2: ARM | F2: THIGH | Q2: MAHON PERFORMANCE
B3: 1
B4: 2
B5: 3
B6: 4
B7: 5
B8: 6
B9: 7
B10: 8
B11: 9
B12: 10
B13: 11
B14: 12
... B54: 52
B55: Template and Design by Lucia Hughes

Sheet Resistance Training
B1: MAHON PERFORMANCE
D3: NAME
D4: START DATE
D5: WEEK ON PROGRAMME | F5: =IF(ISBLANK(F4),"",ROUNDUP((TODAY()-F4)/7,0))
B7: DAY 1
B8: ORDER | C8: EXERCISE | D8: SETS | E8: REPS | F8: TEMPO | J8: INTENSITY | K8: NOTES | L8: VIDEO LINK
C9: Seated Hamstring Curl | D9: 2 | E9: 45881 | F9: 3 | G9: 0 | H9: 1 | I9: 1 | K9: =IF(ISBLANK(C9),"",IFERROR((VLOOKUP(C9,'Exercise List'!$C:$E,2,FALSE)),"")) & " " & "" | L9: =IF(ISBLANK(C9),"",IF(ISBLANK(VLOOKUP(C9,'Exercise List'!$C:$E,3,FALSE)),"",IFERROR(HYPERLINK(VLOOKUP(C9,'Exercise List'!$C:$E,3,FALSE),"Link"),"")))
C10: Hack Squat | D10: 2 | E10: 45785 | F10: 3 | G10: 0 | H10: 1 | I10: 1
C11: RDL | D11: 2 | E11: 5-8 8-12 | F11: 3 | G11: 0 | H11: 1 | I11: 1 | K11: =IF(ISBLANK(C11),"",IFERROR((VLOOKUP(C11,'Exercise List'!$C:$E,2,FALSE)),"")) & " " & "" | L11: =IF(ISBLANK(C11),"",IF(ISBLANK(VLOOKUP(C11,'Exercise List'!$C:$E,3,FALSE)),"",IFERROR(HYPERLINK(VLOOKUP(C11,'Exercise List'!$C:$E,3,FALSE),"Link"),"")))
C12: FFE Split Squat | D12: 2 | E12: 45881 | F12: 3 | G12: 0 | H12: 1 | I12: 1 | K12: =IF(ISBLANK(C12),"",IFERROR((VLOOKUP(C12,'Exercise List'!$C:$E,2,FALSE)),"")) & " " & "" | L12: =IF(ISBLANK(C12),"",IF(ISBLANK(VLOOKUP(C12,'Exercise List'!$C:$E,3,FALSE)),"",IFERROR(HYPERLINK(VLOOKUP(C12,'Exercise List'!$C:$E,3,FALSE),"Link"),"")))
C13: Leg Press | D13: 2 | E13: 45881 | F13: 3 | G13: 0 | H13: 1 | I13: 1 | K13: =IF(ISBLANK(C13),"",IFERROR((VLOOKUP(C13,'Exercise List'!$C:$E,2,FALSE)),"")) & " " & "" | L13: =IF(ISBLANK(C13),"",IF(ISBLANK(VLOOKUP(C13,'Exercise List'!$C:$E,3,FALSE)),"",IFERROR(HYPERLINK(VLOOKUP(C13,'Exercise List'!$C:$E,3,FALSE),"Link"),"")))
C14: Glute Kickback | D14: 2 | E14: 45881 | F14: 3 | G14: 0 | H14: 1 | I14: 1 | K14: =IF(ISBLANK(C14),"",IFERROR((VLOOKUP(C14,'Exercise List'!$C:$E,2,FALSE)),"")) & " " & "" | L14: =IF(ISBLANK(C14),"",IF(ISBLANK(VLOOKUP(C14,'Exercise List'!$C:$E,3,FALSE)),"",IFERROR(HYPERLINK(VLOOKUP(C14,'Exercise List'!$C:$E,3,FALSE),"Link"),"")))
K15: =IF(ISBLANK(C15),"",IFERROR((VLOOKUP(C15,'Exercise List'!$C:$E,2,FALSE)),"")) & " " & "" | L15: =IF(ISBLANK(C15),"",IF(ISBLANK(VLOOKUP(C15,'Exercise List'!$C:$E,3,FALSE)),"",IFERROR(HYPERLINK(VLOOKUP(C15,'Exercise List'!$C:$E,3,FALSE),"Link"),"")))
K16: =IF(ISBLANK(C16),"",IFERROR((VLOOKUP(C16,'Exercise List'!$C:$E,2,FALSE)),"")) & " " & "" | L16: =IF(ISBLANK(C16),"",IF(ISBLANK(VLOOKUP(C16,'Exercise List'!$C:$E,3,FALSE)),"",IFERROR(HYPERLINK(VLOOKUP(C16,'Exercise List'!$C:$E,3,FALSE),"Link"),"")))
K17: =IF(ISBLANK(C17),"",IFERROR((VLOOKUP(C17,'Exercise List'!$C:$E,2,FALSE)),"")) & " " & "" | L17: =IF(ISBLANK(C17),"",IF(ISBLANK(VLOOKUP(C17,'Exercise List'!$C:$E,3,FALSE)),"",IFERROR(HYPERLINK(VLOOKUP(C17,'Exercise List'!$C:$E,3,FALSE),"Link"),"")))
K18: =IF(ISBLANK(C18),"",IFERROR((VLOOKUP(C18,'Exercise List'!$C:$E,2,FALSE)),"")) & " " & "" | L18: =IF(ISBLANK(C18),"",IF(ISBLANK(VLOOKUP(C18,'Exercise List'!$C:$E,3,FALSE)),"",IFERROR(HYPERLINK(VLOOKUP(C18,'Exercise List'!$C:$E,3,FALSE),"Link"),"")))
K19: =IF(ISBLANK(C19),"",IFERROR((VLOOKUP(C19,'Exercise List'!$C:$E,2,FALSE)),"")) & " " & "" | L19: =IF(ISBLANK(C19),"",IF(ISBLANK(VLOOKUP(C19,'Exercise List'!$C:$E,3,FALSE)),"",IFERROR(HYPERLINK(VLOOKUP(C19,'Exercise List'!$C:$E,3,FALSE),"Link"),"")))
K20: =IF(ISBLANK(C20),"",IFERROR((VLOOKUP(C20,'Exercise List'!$C:$E,2,FALSE)),"")) & " " & "" | L20: =IF(ISBLANK(C20),"",IF(ISBLANK(VLOOKUP(C20,'Exercise List'!$C:$E,3,FALSE)),"",IFERROR(HYPERLINK(VLOOKUP(C20,'Exercise List'!$C:$E,3,FALSE),"Link"),"")))
K21: =IF(ISBLANK(C21),"",IFERROR((VLOOKUP(C21,'Exercise List'!$C:$E,2,FALSE)),"")) & " " & "" | L21: =IF(ISBLANK(C21),"",IF(ISBLANK(VLOOKUP(C21,'Exercise List'!$C:$E,3,FALSE)),"",IFERROR(HYPERLINK(VLOOKUP(C21,'Exercise List'!$C:$E,3,FALSE),"Link"),"")))
K22: =IF(ISBLANK(C22),"",IFERROR((VLOOKUP(C22,'Exercise List'!$C:$E,2,FALSE)),"")) & " " & "" | L22: =IF(ISBLANK(C22),"",IF(ISBLANK(VLOOKUP(C22,'Exercise List'!$C:$E,3,FALSE)),"",IFERROR(HYPERLINK(VLOOKUP(C22,'Exercise List'!$C:$E,3,FALSE),"Link"),"")))
K23: =IF(ISBLANK(C23),"",IFERROR((VLOOKUP(C23,'Exercise List'!$C:$E,2,FALSE)),"")) & " " & "" | L23: =IF(ISBLANK(C23),"",IF(ISBLANK(VLOOKUP(C23,'Exercise List'!$C:$E,3,FALSE)),"",IFERROR(HYPERLINK(VLOOKUP(C23,'Exercise List'!$C:$E,3,FALSE),"Link"),"")))
B25: DAY 2
B26: ORDER | C26: EXERCISE | D26: SETS | E26: REPS | F26: TEMPO | J26: INTENSITY | K26: NOTES | L26: VIDEO LINK
C27: Lat Pulldown | D27: 2 | E27: 5-8 8-12 | F27: 3 | G27: 0 | H27: 1 | I27: 1 | K27: =IF(ISBLANK(C27),"",IFERROR((VLOOKUP(C27,'Exercise List'!$C:$E,2,FALSE)),"")) & " " & "" | L27: =IF(ISBLANK(C27),"",IF(ISBLANK(VLOOKUP(C27,'Exercise List'!$C:$E,3,FALSE)),"",IFERROR(HYPERLINK(VLOOKUP(C27,'Exercise List'!$C:$E,3,FALSE),"Link"),"")))
C28: Hammer Strength Shoulder Press | D28: 2 | E28: 5-8 8-12 | F28: 3 | G28: 0 | H28: 1 | I28: 1 | K28: =IF(ISBLANK(C28),"",IFERROR((VLOOKUP(C28,'Exercise List'!$C:$E,2,FALSE)),"")) & " " & "" | L28: =IF(ISBLANK(C28),"",IF(ISBLANK(VLOOKUP(C28,'Exercise List'!$C:$E,3,FALSE)),"",IFERROR(HYPERLINK(VLOOKUP(C28,'Exercise List'!$C:$E,3,FALSE),"Link"),"")))
C29: Dumbbell Lateral raise | D29: 2 | E29: 5-8 8-12 | F29: 3 | G29: 0 | H29: 1 | I29: 1 | K29: =IF(ISBLANK(C29),"",IFERROR((VLOOKUP(C29,'Exercise List'!$C:$E,2,FALSE)),"")) & " " & "" | L29: =IF(ISBLANK(C29),"",IF(ISBLANK(VLOOKUP(C29,'Exercise List'!$C:$E,3,FALSE)),"",IFERROR(HYPERLINK(VLOOKUP(C29,'Exercise List'!$C:$E,3,FALSE),"Link"),"")))
C30: Dumbbell Bench Press | D30: 2 | E30: 5-8 8-12 | F30: 3 | G30: 0 | H30: 1 | I30: 1 | K30: =IF(ISBLANK(C30),"",IFERROR((VLOOKUP(C30,'Exercise List'!$C:$E,2,FALSE)),"")) & " " & "" | L30: =IF(ISBLANK(C30),"",IF(ISBLANK(VLOOKUP(C30,'Exercise List'!$C:$E,3,FALSE)),"",IFERROR(HYPERLINK(VLOOKUP(C30,'Exercise List'!$C:$E,3,FALSE),"Link"),"")))
C31: Cable Row | D31: 2 | E31: 5-8 8-12 | F31: 3 | G31: 0 | H31: 1 | I31: 1 | K31: =IF(ISBLANK(C31),"",IFERROR((VLOOKUP(C31,'Exercise List'!$C:$E,2,FALSE)),"")) & " " & "" | L31: =IF(ISBLANK(C31),"",IF(ISBLANK(VLOOKUP(C31,'Exercise List'!$C:$E,3,FALSE)),"",IFERROR(HYPERLINK(VLOOKUP(C31,'Exercise List'!$C:$E,3,FALSE),"Link"),"")))
C32: Cable Curl | D32: 2 | E32: 5-8 8-12 | F32: 3 | G32: 0 | H32: 1 | I32: 1 | K32: =IF(ISBLANK(C32),"",IFERROR((VLOOKUP(C32,'Exercise List'!$C:$E,2,FALSE)),"")) & " " & "" | L32: =IF(ISBLANK(C32),"",IF(ISBLANK(VLOOKUP(C32,'Exercise List'!$C:$E,3,FALSE)),"",IFERROR(HYPERLINK(VLOOKUP(C32,'Exercise List'!$C:$E,3,FALSE),"Link"),"")))
C33: Cable Pushdown | D33: 2 | E33: 5-8 8-12 | F33: 3 | G33: 0 | H33: 1 | I33: 1 | K33: =IF(ISBLANK(C33),"",IFERROR((VLOOKUP(C33,'Exercise List'!$C:$E,2,FALSE)),"")) & " " & "" | L33: =IF(ISBLANK(C33),"",IF(ISBLANK(VLOOKUP(C33,'Exercise List'!$C:$E,3,FALSE)),"",IFERROR(HYPERLINK(VLOOKUP(C33,'Exercise List'!$C:$E,3,FALSE),"Link"),"")))
K34: =IF(ISBLANK(C34),"",IFERROR((VLOOKUP(C34,'Exercise List'!$C:$E,2,FALSE)),"")) & " " & "" | L34: =IF(ISBLANK(C34),"",IF(ISBLANK(VLOOKUP(C34,'Exercise List'!$C:$E,3,FALSE)),"",IFERROR(HYPERLINK(VLOOKUP(C34,'Exercise List'!$C:$E,3,FALSE),"Link"),"")))
K35: =IF(ISBLANK(C35),"",IFERROR((VLOOKUP(C35,'Exercise List'!$C:$E,2,FALSE)),"")) & " " & "" | L35: =IF(ISBLANK(C35),"",IF(ISBLANK(VLOOKUP(C35,'Exercise List'!$C:$E,3,FALSE)),"",IFERROR(HYPERLINK(VLOOKUP(C35,'Exercise List'!$C:$E,3,FALSE),"Link"),"")))
K36: =IF(ISBLANK(C36),"",IFERROR((VLOOKUP(C36,'Exercise List'!$C:$E,2,FALSE)),"")) & " " & "" | L36: =IF(ISBLANK(C36),"",IF(ISBLANK(VLOOKUP(C36,'Exercise List'!$C:$E,3,FALSE)),"",IFERROR(HYPERLINK(VLOOKUP(C36,'Exercise List'!$C:$E,3,FALSE),"Link"),"")))
K37: =IF(ISBLANK(C37),"",IFERROR((VLOOKUP(C37,'Exercise List'!$C:$E,2,FALSE)),"")) & " " & "" | L37: =IF(ISBLANK(C37),"",IF(ISBLANK(VLOOKUP(C37,'Exercise List'!$C:$E,3,FALSE)),"",IFERROR(HYPERLINK(VLOOKUP(C37,'Exercise List'!$C:$E,3,FALSE),"Link"),"")))
K38: =IF(ISBLANK(C38),"",IFERROR((VLOOKUP(C38,'Exercise List'!$C:$E,2,FALSE)),"")) & " " & "" | L38: =IF(ISBLANK(C38),"",IF(ISBLANK(VLOOKUP(C38,'Exercise List'!$C:$E,3,FALSE)),"",IFERROR(HYPERLINK(VLOOKUP(C38,'Exercise List'!$C:$E,3,FALSE),"Link"),"")))
K39: =IF(ISBLANK(C39),"",IFERROR((VLOOKUP(C39,'Exercise List'!$C:$E,2,FALSE)),"")) & " " & "" | L39: =IF(ISBLANK(C39),"",IF(ISBLANK(VLOOKUP(C39,'Exercise List'!$C:$E,3,FALSE)),"",IFERROR(HYPERLINK(VLOOKUP(C39,'Exercise List'!$C:$E,3,FALSE),"Link"),"")))
K40: =IF(ISBLANK(C40),"",IFERROR((VLOOKUP(C40,'Exercise List'!$C:$E,2,FALSE)),"")) & " " & "" | L40: =IF(ISBLANK(C40),"",IF(ISBLANK(VLOOKUP(C40,'Exercise List'!$C:$E,3,FALSE)),"",IFERROR(HYPERLINK(VLOOKUP(C40,'Exercise List'!$C:$E,3,FALSE),"Link"),"")))
K41: =IF(ISBLANK(C41),"",IFERROR((VLOOKUP(C41,'Exercise List'!$C:$E,2,FALSE)),"")) & " " & "" | L41: =IF(ISBLANK(C41),"",IF(ISBLANK(VLOOKUP(C41,'Exercise List'!$C:$E,3,FALSE)),"",IFERROR(HYPERLINK(VLOOKUP(C41,'Exercise List'!$C:$E,3,FALSE),"Link"),"")))
B43: DAY 3
B44: ORDER | C44: EXERCISE | D44: SETS | E44: REPS | F44: TEMPO | J44: INTENSITY | K44: NOTES | L44: VIDEO LINK
...

Sheet Sheet10

Sheet Sheet9

Sheet Meal Plan - 2 Day
B1: MAHON PERFORMANCE
E2: DAY | F2: CALS | G2: PRO | H2: CHO | I2: FAT
E3: TD | F3: =G54 -> 1401.8 | G3: =H54 -> 133.43 | H3: =I54 -> 182.6 | I3: =J54 -> 15.525
E4: NTD | F4: =Q54 -> 1134.5 | G4: =R54 -> 98.45 | H4: =S54 -> 134.7 | I4: =T54 -> 21.5
B6: TRAINING DAY | L6: NON-TRAINING DAY
B7: MEAL NO. | D7: FOOD | E7: PORTION | F7: NO. OF PORTIONS | G7: CALS | H7: PRO | I7: CHO | J7: FAT | L7: MEAL NO. | N7: FOOD | O7: PORTION | P7: NO. OF PORTIONS | Q7: CALS | R7: PRO | S7: CHO | T7: FAT
B8: M1 | D8: Oats | E8: =IF(ISBLANK(D8),"",IFERROR((VLOOKUP(D8,'Food List'!$C:$H,2,FALSE)),"")) -> 100g | F8: 0.5 | G8: =IF(ISBLANK(F8),"",IFERROR((VLOOKUP(D8,'Food List'!$C:$H,3,FALSE))*F8,"")) -> 187 | H8: =IF(ISBLANK(F8),"",IFERROR((VLOOKUP(D8,'Food List'!$C:$H,4,FALSE))*F8,"")) -> 5.45 | I8: =IF(ISBLANK(F8),"",IFERROR((VLOOKUP(D8,'Food List'!$C:$H,5,FALSE))*F8,"")) -> 32 | J8: =IF(ISBLANK(F8),"",IFERROR((VLOOKUP(D8,'Food List'!$C:$H,6,FALSE))*F8,"")) -> 4.05 | L8: M1 | N8: Plain Bagel | O8: =IF(ISBLANK(N8),"",IFERROR((VLOOKUP(N8,'Food List'!$C:$H,2,FALSE)),"")) -> 1 bagel | P8: 1 | Q8: =IF(ISBLANK(P8),"",IFERROR((VLOOKUP(N8,'Food List'!$C:$H,3,FALSE))*P8,"")) -> 224 | R8: =IF(ISBLANK(P8),"",IFERROR((VLOOKUP(N8,'Food List'!$C:$H,4,FALSE))*P8,"")) -> 8.5 | S8: =IF(ISBLANK(P8),"",IFERROR((VLOOKUP(N8,'Food List'!$C:$H,5,FALSE))*P8,"")) -> 43.8 | T8: =IF(ISBLANK(P8),"",IFERROR((VLOOKUP(N8,'Food List'!$C:$H,6,FALSE))*P8,"")) -> 1.2
D9: Blueberries | E9: =IF(ISBLANK(D9),"",IFERROR((VLOOKUP(D9,'Food List'!$C:$H,2,FALSE)),"")) -> 100g | F9: 1 | G9: =IF(ISBLANK(F9),"",IFERROR((VLOOKUP(D9,'Food List'!$C:$H,3,FALSE))*F9,"")) -> 42 | H9: =IF(ISBLANK(F9),"",IFERROR((VLOOKUP(D9,'Food List'!$C:$H,4,FALSE))*F9,"")) -> 0.9 | I9: =IF(ISBLANK(F9),"",IFERROR((VLOOKUP(D9,'Food List'!$C:$H,5,FALSE))*F9,"")) -> 9.1 | J9: =IF(ISBLANK(F9),"",IFERROR((VLOOKUP(D9,'Food List'!$C:$H,6,FALSE))*F9,"")) -> 0.2 | N9: Eggs Whole | O9: =IF(ISBLANK(N9),"",IFERROR((VLOOKUP(N9,'Food List'!$C:$H,2,FALSE)),"")) -> 1 egg | P9: 1 | Q9: =IF(ISBLANK(P9),"",IFERROR((VLOOKUP(N9,'Food List'!$C:$H,3,FALSE))*P9,"")) -> 72 | R9: =IF(ISBLANK(P9),"",IFERROR((VLOOKUP(N9,'Food List'!$C:$H,4,FALSE))*P9,"")) -> 6 | S9: =IF(ISBLANK(P9),"",IFERROR((VLOOKUP(N9,'Food List'!$C:$H,5,FALSE))*P9,"")) -> 0.4 | T9: =IF(ISBLANK(P9),"",IFERROR((VLOOKUP(N9,'Food List'!$C:$H,6,FALSE))*P9,"")) -> 4.8
D10: Honey | E10: =IF(ISBLANK(D10),"",IFERROR((VLOOKUP(D10,'Food List'!$C:$H,2,FALSE)),"")) -> 100g | F10: 0.25 | G10: =IF(ISBLANK(F10),"",IFERROR((VLOOKUP(D10,'Food List'!$C:$H,3,FALSE))*F10,"")) -> 76.75 | H10: =IF(ISBLANK(F10),"",IFERROR((VLOOKUP(D10,'Food List'!$C:$H,4,FALSE))*F10,"")) -> 0.1 | I10: =IF(ISBLANK(F10),"",IFERROR((VLOOKUP(D10,'Food List'!$C:$H,5,FALSE))*F10,"")) -> 19 | J10: =IF(ISBLANK(F10),"",IFERROR((VLOOKUP(D10,'Food List'!$C:$H,6,FALSE))*F10,"")) -> 0 | N10: Turkey Rasher | O10: =IF(ISBLANK(N10),"",IFERROR((VLOOKUP(N10,'Food List'!$C:$H,2,FALSE)),"")) -> 1 rasher | P10: 2 | Q10: =IF(ISBLANK(P10),"",IFERROR((VLOOKUP(N10,'Food List'!$C:$H,3,FALSE))*P10,"")) -> 58 | R10: =IF(ISBLANK(P10),"",IFERROR((VLOOKUP(N10,'Food List'!$C:$H,4,FALSE))*P10,"")) -> 10.2 | S10: =IF(ISBLANK(P10),"",IFERROR((VLOOKUP(N10,'Food List'!$C:$H,5,FALSE))*P10,"")) -> 1 | T10: =IF(ISBLANK(P10),"",IFERROR((VLOOKUP(N10,'Food List'!$C:$H,6,FALSE))*P10,"")) -> 1.4
D11: Whey Protein | E11: =IF(ISBLANK(D11),"",IFERROR((VLOOKUP(D11,'Food List'!$C:$H,2,FALSE)),"")) -> 100g | F11: 0.25 | G11: =IF(ISBLANK(F11),"",IFERROR((VLOOKUP(D11,'Food List'!$C:$H,3,FALSE))*F11,"")) -> 94.75 | H11: =IF(ISBLANK(F11),"",IFERROR((VLOOKUP(D11,'Food List'!$C:$H,4,FALSE))*F11,"")) -> 22.5 | I11: =IF(ISBLANK(F11),"",IFERROR((VLOOKUP(D11,'Food List'!$C:$H,5,FALSE))*F11,"")) -> 0.35 | J11: =IF(ISBLANK(F11),"",IFERROR((VLOOKUP(D11,'Food List'!$C:$H,6,FALSE))*F11,"")) -> 0.375 | O11: =IF(ISBLANK(N11),"",IFERROR((VLOOKUP(N11,'Food List'!$C:$H,2,FALSE)),"")) | Q11: =IF(ISBLANK(P11),"",IFERROR((VLOOKUP(N11,'Food List'!$C:$H,3,FALSE))*P11,"")) | R11: =IF(ISBLANK(P11),"",IFERROR((VLOOKUP(N11,'Food List'!$C:$H,4,FALSE))*P11,"")) | S11: =IF(ISBLANK(P11),"",IFERROR((VLOOKUP(N11,'Food List'!$C:$H,5,FALSE))*P11,"")) | T11: =IF(ISBLANK(P11),"",IFERROR((VLOOKUP(N11,'Food List'!$C:$H,6,FALSE))*P11,""))
E12: =IF(ISBLANK(D12),"",IFERROR((VLOOKUP(D12,'Food List'!$C:$H,2,FALSE)),"")) | G12: =IF(ISBLANK(F12),"",IFERROR((VLOOKUP(D12,'Food List'!$C:$H,3,FALSE))*F12,"")) | H12: =IF(ISBLANK(F12),"",IFERROR((VLOOKUP(D12,'Food List'!$C:$H,4,FALSE))*F12,"")) | I12: =IF(ISBLANK(F12),"",IFERROR((VLOOKUP(D12,'Food List'!$C:$H,5,FALSE))*F12,"")) | J12: =IF(ISBLANK(F12),"",IFERROR((VLOOKUP(D12,'Food List'!$C:$H,6,FALSE))*F12,"")) | O12: =IF(ISBLANK(N12),"",IFERROR((VLOOKUP(N12,'Food List'!$C:$H,2,FALSE)),"")) | Q12: =IF(ISBLANK(P12),"",IFERROR((VLOOKUP(N12,'Food List'!$C:$H,3,FALSE))*P12,"")) | R12: =IF(ISBLANK(P12),"",IFERROR((VLOOKUP(N12,'Food List'!$C:$H,4,FALSE))*P12,"")) | S12: =IF(ISBLANK(P12),"",IFERROR((VLOOKUP(N12,'Food List'!$C:$H,5,FALSE))*P12,"")) | T12: =IF(ISBLANK(P12),"",IFERROR((VLOOKUP(N12,'Food List'!$C:$H,6,FALSE))*P12,""))
E13: =IF(ISBLANK(D13),"",IFERROR((VLOOKUP(D13,'Food List'!$C:$H,2,FALSE)),"")) | G13: =IF(ISBLANK(F13),"",IFERROR((VLOOKUP(D13,'Food List'!$C:$H,3,FALSE))*F13,"")) | H13: =IF(ISBLANK(F13),"",IFERROR((VLOOKUP(D13,'Food List'!$C:$H,4,FALSE))*F13,"")) | I13: =IF(ISBLANK(F13),"",IFERROR((VLOOKUP(D13,'Food List'!$C:$H,5,FALSE))*F13,"")) | J13: =IF(ISBLANK(F13),"",IFERROR((VLOOKUP(D13,'Food List'!$C:$H,6,FALSE))*F13,"")) | O13: =IF(ISBLANK(N13),"",IFERROR((VLOOKUP(N13,'Food List'!$C:$H,2,FALSE)),"")) | Q13: =IF(ISBLANK(P13),"",IFERROR((VLOOKUP(N13,'Food List'!$C:$H,3,FALSE))*P13,"")) | R13: =IF(ISBLANK(P13),"",IFERROR((VLOOKUP(N13,'Food List'!$C:$H,4,FALSE))*P13,"")) | S13: =IF(ISBLANK(P13),"",IFERROR((VLOOKUP(N13,'Food List'!$C:$H,5,FALSE))*P13,"")) | T13: =IF(ISBLANK(P13),"",IFERROR((VLOOKUP(N13,'Food List'!$C:$H,6,FALSE))*P13,""))
D14: MEAL TOTAL | G14: =IFERROR(SUM(G8:G13),0) -> 400.5 | H14: =IFERROR(SUM(H8:H13),0) -> 28.95 | I14: =IFERROR(SUM(I8:I13),0) -> 60.45 | J14: =IFERROR(SUM(J8:J13),0) -> 4.625 | N14: MEAL TOTAL | Q14: =IFERROR(SUM(Q8:Q13),0) -> 354 | R14: =IFERROR(SUM(R8:R13),0) -> 24.7 | S14: =IFERROR(SUM(S8:S13),0) -> 45.2 | T14: =IFERROR(SUM(T8:T13),0) -> 7.4
B16: M2 | D16: Chicken Breast (Raw) | E16: =IF(ISBLANK(D16),"",IFERROR((VLOOKUP(D16,'Food List'!$C:$H,2,FALSE)),"")) -> 100g | F16: 1.5 | G16: =IF(ISBLANK(F16),"",IFERROR((VLOOKUP(D16,'Food List'!$C:$H,3,FALSE))*F16,"")) -> 159 | H16: =IF(ISBLANK(F16),"",IFERROR((VLOOKUP(D16,'Food List'!$C:$H,4,FALSE))*F16,"")) -> 36 | I16: =IF(ISBLANK(F16),"",IFERROR((VLOOKUP(D16,'Food List'!$C:$H,5,FALSE))*F16,"")) -> 0 | J16: =IF(ISBLANK(F16),"",IFERROR((VLOOKUP(D16,'Food List'!$C:$H,6,FALSE))*F16,"")) -> 1.65 | L16: M2 | N16: Chicken Breast (Raw) | O16: =IF(ISBLANK(N16),"",IFERROR((VLOOKUP(N16,'Food List'!$C:$H,2,FALSE)),"")) -> 100g | P16: 1.5 | Q16: =IF(ISBLANK(P16),"",IFERROR((VLOOKUP(N16,'Food List'!$C:$H,3,FALSE))*P16,"")) -> 159 | R16: =IF(ISBLANK(P16),"",IFERROR((VLOOKUP(N16,'Food List'!$C:$H,4,FALSE))*P16,"")) -> 36 | S16: =IF(ISBLANK(P16),"",IFERROR((VLOOKUP(N16,'Food List'!$C:$H,5,FALSE))*P16,"")) -> 0 | T16: =IF(ISBLANK(P16),"",IFERROR((VLOOKUP(N16,'Food List'!$C:$H,6,FALSE))*P16,"")) -> 1.65
D17: Country Mix Vegetables | E17: =IF(ISBLANK(D17),"",IFERROR((VLOOKUP(D17,'Food List'!$C:$H,2,FALSE)),"")) -> 100g | F17: 1 | G17: =IF(ISBLANK(F17),"",IFERROR((VLOOKUP(D17,'Food List'!$C:$H,3,FALSE))*F17,"")) -> 36 | H17: =IF(ISBLANK(F17),"",IFERROR((VLOOKUP(D17,'Food List'!$C:$H,4,FALSE))*F17,"")) -> 2.7 | I17: =IF(ISBLANK(F17),"",IFERROR((VLOOKUP(D17,'Food List'!$C:$H,5,FALSE))*F17,"")) -> 4.9 | J17: =IF(ISBLANK(F17),"",IFERROR((VLOOKUP(D17,'Food List'!$C:$H,6,FALSE))*F17,"")) -> 0.6 | N17: Country Mix Vegetables | O17: =IF(ISBLANK(N17),"",IFERROR((VLOOKUP(N17,'Food List'!$C:$H,2,FALSE)),"")) -> 100g | P17: 2 | Q17: =IF(ISBLANK(P17),"",IFERROR((VLOOKUP(N17,'Food List'!$C:$H,3,FALSE))*P17,"")) -> 72 | R17: =IF(ISBLANK(P17),"",IFERROR((VLOOKUP(N17,'Food List'!$C:$H,4,FALSE))*P17,"")) -> 5.4 | S17: =IF(ISBLANK(P17),"",IFERROR((VLOOKUP(N17,'Food List'!$C:$H,5,FALSE))*P17,"")) -> 9.8 | T17: =IF(ISBLANK(P17),"",IFERROR((VLOOKUP(N17,'Food List'!$C:$H,6,FALSE))*P17,"")) -> 1.2
D18: Apple | E18: =IF(ISBLANK(D18),"",IFERROR((VLOOKUP(D18,'Food List'!$C:$H,2,FALSE)),"")) -> 100g | F18: 1.7 | G18: =IF(ISBLANK(F18),"",IFERROR((VLOOKUP(D18,'Food List'!$C:$H,3,FALSE))*F18,"")) -> 90.1 | H18: =IF(ISBLANK(F18),"",IFERROR((VLOOKUP(D18,'Food List'!$C:$H,4,FALSE))*F18,"")) -> 1.02 | I18: =IF(ISBLANK(F18),"",IFERROR((VLOOKUP(D18,'Food List'!$C:$H,5,FALSE))*F18,"")) -> 19.55 | J18: =IF(ISBLANK(F18),"",IFERROR((VLOOKUP(D18,'Food List'!$C:$H,6,FALSE))*F18,"")) -> 0.85 | N18: White Potato | O18: =IF(ISBLANK(N18),"",IFERROR((VLOOKUP(N18,'Food List'!$C:$H,2,FALSE)),"")) -> 100g | P18: 2 | Q18: =IF(ISBLANK(P18),"",IFERROR((VLOOKUP(N18,'Food List'!$C:$H,3,FALSE))*P18,"")) -> 160 | R18: =IF(ISBLANK(P18),"",IFERROR((VLOOKUP(N18,'Food List'!$C:$H,4,FALSE))*P18,"")) -> 3.8 | S18: =IF(ISBLANK(P18),"",IFERROR((VLOOKUP(N18,'Food List'!$C:$H,5,FALSE))*P18,"")) -> 35.8 | T18: =IF(ISBLANK(P18),"",IFERROR((VLOOKUP(N18,'Food List'!$C:$H,6,FALSE))*P18,"")) -> 0.2
E19: =IF(ISBLANK(D19),"",IFERROR((VLOOKUP(D19,'Food List'!$C:$H,2,FALSE)),"")) | G19: =IF(ISBLANK(F19),"",IFERROR((VLOOKUP(D19,'Food List'!$C:$H,3,FALSE))*F19,"")) | H19: =IF(ISBLANK(F19),"",IFERROR((VLOOKUP(D19,'Food List'!$C:$H,4,FALSE))*F19,"")) | I19: =IF(ISBLANK(F19),"",IFERROR((VLOOKUP(D19,'Food List'!$C:$H,5,FALSE))*F19,"")) | J19: =IF(ISBLANK(F19),"",IFERROR((VLOOKUP(D19,'Food List'!$C:$H,6,FALSE))*F19,"")) | O19: =IF(ISBLANK(N19),"",IFERROR((VLOOKUP(N19,'Food List'!$C:$H,2,FALSE)),"")) | Q19: =IF(ISBLANK(P19),"",IFERROR((VLOOKUP(N19,'Food List'!$C:$H,3,FALSE))*P19,"")) | R19: =IF(ISBLANK(P19),"",IFERROR((VLOOKUP(N19,'Food List'!$C:$H,4,FALSE))*P19,"")) | S19: =IF(ISBLANK(P19),"",IFERROR((VLOOKUP(N19,'Food List'!$C:$H,5,FALSE))*P19,"")) | T19: =IF(ISBLANK(P19),"",IFERROR((VLOOKUP(N19,'Food List'!$C:$H,6,FALSE))*P19,""))
E20: =IF(ISBLANK(D20),"",IFERROR((VLOOKUP(D20,'Food List'!$C:$H,2,FALSE)),"")) | G20: =IF(ISBLANK(F20),"",IFERROR((VLOOKUP(D20,'Food List'!$C:$H,3,FALSE))*F20,"")) | H20: =IF(ISBLANK(F20),"",IFERROR((VLOOKUP(D20,'Food List'!$C:$H,4,FALSE))*F20,"")) | I20: =IF(ISBLANK(F20),"",IFERROR((VLOOKUP(D20,'Food List'!$C:$H,5,FALSE))*F20,"")) | J20: =IF(ISBLANK(F20),"",IFERROR((VLOOKUP(D20,'Food List'!$C:$H,6,FALSE))*F20,"")) | O20: =IF(ISBLANK(N20),"",IFERROR((VLOOKUP(N20,'Food List'!$C:$H,2,FALSE)),"")) | Q20: =IF(ISBLANK(P20),"",IFERROR((VLOOKUP(N20,'Food List'!$C:$H,3,FALSE))*P20,"")) | R20: =IF(ISBLANK(P20),"",IFERROR((VLOOKUP(N20,'Food List'!$C:$H,4,FALSE))*P20,"")) | S20: =IF(ISBLANK(P20),"",IFERROR((VLOOKUP(N20,'Food List'!$C:$H,5,FALSE))*P20,"")) | T20: =IF(ISBLANK(P20),"",IFERROR((VLOOKUP(N20,'Food List'!$C:$H,6,FALSE))*P20,""))
E21: =IF(ISBLANK(D21),"",IFERROR((VLOOKUP(D21,'Food List'!$C:$H,2,FALSE)),"")) | G21: =IF(ISBLANK(F21),"",IFERROR((VLOOKUP(D21,'Food List'!$C:$H,3,FALSE))*F21,"")) | H21: =IF(ISBLANK(F21),"",IFERROR((VLOOKUP(D21,'Food List'!$C:$H,4,FALSE))*F21,"")) | I21: =IF(ISBLANK(F21),"",IFERROR((VLOOKUP(D21,'Food List'!$C:$H,5,FALSE))*F21,"")) | J21: =IF(ISBLANK(F21),"",IFERROR((VLOOKUP(D21,'Food List'!$C:$H,6,FALSE))*F21,"")) | O21: =IF(ISBLANK(N21),"",IFERROR((VLOOKUP(N21,'Food List'!$C:$H,2,FALSE)),"")) | Q21: =IF(ISBLANK(P21),"",IFERROR((VLOOKUP(N21,'Food List'!$C:$H,3,FALSE))*P21,"")) | R21: =IF(ISBLANK(P21),"",IFERROR((VLOOKUP(N21,'Food List'!$C:$H,4,FALSE))*P21,"")) | S21: =IF(ISBLANK(P21),"",IFERROR((VLOOKUP(N21,'Food List'!$C:$H,5,FALSE))*P21,"")) | T21: =IF(ISBLANK(P21),"",IFERROR((VLOOKUP(N21,'Food List'!$C:$H,6,FALSE))*P21,""))
D22: MEAL TOTAL | G22: =IFERROR(SUM(G16:G21),0) -> 285.1 | H22: =IFERROR(SUM(H16:H21),0) -> 39.72 | I22: =IFERROR(SUM(I16:I21),0) -> 24.45 | J22: =IFERROR(SUM(J16:J21),0) -> 3.1 | N22: MEAL TOTAL | Q22: =IFERROR(SUM(Q16:Q21),0) -> 391 | R22: =IFERROR(SUM(R16:R21),0) -> 45.2 | S22: =IFERROR(SUM(S16:S21),0) -> 45.6 | T22: =IFERROR(SUM(T16:T21),0) -> 3.05
B24: M3 | D24: Chicken Breast (Raw) | E24: =IF(ISBLANK(D24),"",IFERROR((VLOOKUP(D24,'Food List'!$C:$H,2,FALSE)),"")) -> 100g | F24: 1.5 | G24: =IF(ISBLANK(F24),"",IFERROR((VLOOKUP(D24,'Food List'!$C:$H,3,FALSE))*F24,"")) -> 159 | H24: =IF(ISBLANK(F24),"",IFERROR((VLOOKUP(D24,'Food List'!$C:$H,4,FALSE))*F24,"")) -> 36 | I24: =IF(ISBLANK(F24),"",IFERROR((VLOOKUP(D24,'Food List'!$C:$H,5,FALSE))*F24,"")) -> 0 | J24: =IF(ISBLANK(F24),"",IFERROR((VLOOKUP(D24,'Food List'!$C:$H,6,FALSE))*F24,"")) -> 1.65 | L24: M3 | N24: Salmon (Raw) | O24: =IF(ISBLANK(N24),"",IFERROR((VLOOKUP(N24,'Food List'!$C:$H,2,FALSE)),"")) -> 100g | P24: 1 | Q24: =IF(ISBLANK(P24),"",IFERROR((VLOOKUP(N24,'Food List'!$C:$H,3,FALSE))*P24,"")) -> 179 | R24: =IF(ISBLANK(P24),"",IFERROR((VLOOKUP(N24,'Food List'!$C:$H,4,FALSE))*P24,"")) -> 22.1 | S24: =IF(ISBLANK(P24),"",IFERROR((VLOOKUP(N24,'Food List'!$C:$H,5,FALSE))*P24,"")) -> 0 | T24: =IF(ISBLANK(P24),"",IFERROR((VLOOKUP(N24,'Food List'!$C:$H,6,FALSE))*P24,"")) -> 10.1
D25: Jasmine Rice | E25: =IF(ISBLANK(D25),"",IFERROR((VLOOKUP(D25,'Food List'!$C:$H,2,FALSE)),"")) -> 100g | F25: 0.6 | G25: =IF(ISBLANK(F25),"",IFERROR((VLOOKUP(D25,'Food List'!$C:$H,3,FALSE))*F25,"")) -> 209.4 | H25: =IF(ISBLANK(F25),"",IFERROR((VLOOKUP(D25,'Food List'!$C:$H,4,FALSE))*F25,"")) -> 4.5 | I25: =IF(ISBLANK(F25),"",IFERROR((VLOOKUP(D25,'Food List'!$C:$H,5,FALSE))*F25,"")) -> 46.8 | J25: =IF(ISBLANK(F25),"",IFERROR((VLOOKUP(D25,'Food List'!$C:$H,6,FALSE))*F25,"")) -> 0.42 | N25: Jasmine Rice | O25: =IF(ISBLANK(N25),"",IFERROR((VLOOKUP(N25,'Food List'!$C:$H,2,FALSE)),"")) -> 100g | P25: 0.5 | Q25: =IF(ISBLANK(P25),"",IFERROR((VLOOKUP(N25,'Food List'!$C:$H,3,FALSE))*P25,"")) -> 174.5 | R25: =IF(ISBLANK(P25),"",IFERROR((VLOOKUP(N25,'Food List'!$C:$H,4,FALSE))*P25,"")) -> 3.75 | S25: =IF(ISBLANK(P25),"",IFERROR((VLOOKUP(N25,'Food List'!$C:$H,5,FALSE))*P25,"")) -> 39 | T25: =IF(ISBLANK(P25),"",IFERROR((VLOOKUP(N25,'Food List'!$C:$H,6,FALSE))*P25,"")) -> 0.35
D26: Country Mix Vegetables | E26: =IF(ISBLANK(D26),"",IFERROR((VLOOKUP(D26,'Food List'!$C:$H,2,FALSE)),"")) -> 100g | F26: 1 | G26: =IF(ISBLANK(F26),"",IFERROR((VLOOKUP(D26,'Food List'!$C:$H,3,FALSE))*F26,"")) -> 36 | H26: =IF(ISBLANK(F26),"",IFERROR((VLOOKUP(D26,'Food List'!$C:$H,4,FALSE))*F26,"")) -> 2.7 | I26: =IF(ISBLANK(F26),"",IFERROR((VLOOKUP(D26,'Food List'!$C:$H,5,FALSE))*F26,"")) -> 4.9 | J26: =IF(ISBLANK(F26),"",IFERROR((VLOOKUP(D26,'Food List'!$C:$H,6,FALSE))*F26,"")) -> 0.6 | N26: Country Mix Vegetables | O26: =IF(ISBLANK(N26),"",IFERROR((VLOOKUP(N26,'Food List'!$C:$H,2,FALSE)),"")) -> 100g | P26: 1 | Q26: =IF(ISBLANK(P26),"",IFERROR((VLOOKUP(N26,'Food List'!$C:$H,3,FALSE))*P26,"")) -> 36 | R26: =IF(ISBLANK(P26),"",IFERROR((VLOOKUP(N26,'Food List'!$C:$H,4,FALSE))*P26,"")) -> 2.7 | S26: =IF(ISBLANK(P26),"",IFERROR((VLOOKUP(N26,'Food List'!$C:$H,5,FALSE))*P26,"")) -> 4.9 | T26: =IF(ISBLANK(P26),"",IFERROR((VLOOKUP(N26,'Food List'!$C:$H,6,FALSE))*P26,"")) -> 0.6
E27: =IF(ISBLANK(D27),"",IFERROR((VLOOKUP(D27,'Food List'!$C:$H,2,FALSE)),"")) | G27: =IF(ISBLANK(F27),"",IFERROR((VLOOKUP(D27,'Food List'!$C:$H,3,FALSE))*F27,"")) | H27: =IF(ISBLANK(F27),"",IFERROR((VLOOKUP(D27,'Food List'!$C:$H,4,FALSE))*F27,"")) | I27: =IF(ISBLANK(F27),"",IFERROR((VLOOKUP(D27,'Food List'!$C:$H,5,FALSE))*F27,"")) | J27: =IF(ISBLANK(F27),"",IFERROR((VLOOKUP(D27,'Food List'!$C:$H,6,FALSE))*F27,"")) | O27: =IF(ISBLANK(N27),"",IFERROR((VLOOKUP(N27,'Food List'!$C:$H,2,FALSE)),"")) | Q27: =IF(ISBLANK(P27),"",IFERROR((VLOOKUP(N27,'Food List'!$C:$H,3,FALSE))*P27,"")) | R27: =IF(ISBLANK(P27),"",IFERROR((VLOOKUP(N27,'Food List'!$C:$H,4,FALSE))*P27,"")) | S27: =IF(ISBLANK(P27),"",IFERROR((VLOOKUP(N27,'Food List'!$C:$H,5,FALSE))*P27,"")) | T27: =IF(ISBLANK(P27),"",IFERROR((VLOOKUP(N27,'Food List'!$C:$H,6,FALSE))*P27,""))
E28: =IF(ISBLANK(D28),"",IFERROR((VLOOKUP(D28,'Food List'!$C:$H,2,FALSE)),"")) | G28: =IF(ISBLANK(F28),"",IFERROR((VLOOKUP(D28,'Food List'!$C:$H,3,FALSE))*F28,"")) | H28: =IF(ISBLANK(F28),"",IFERROR((VLOOKUP(D28,'Food List'!$C:$H,4,FALSE))*F28,"")) | I28: =IF(ISBLANK(F28),"",IFERROR((VLOOKUP(D28,'Food List'!$C:$H,5,FALSE))*F28,"")) | J28: =IF(ISBLANK(F28),"",IFERROR((VLOOKUP(D28,'Food List'!$C:$H,6,FALSE))*F28,"")) | O28: =IF(ISBLANK(N28),"",IFERROR((VLOOKUP(N28,'Food List'!$C:$H,2,FALSE)),"")) | Q28: =IF(ISBLANK(P28),"",IFERROR((VLOOKUP(N28,'Food List'!$C:$H,3,FALSE))*P28,"")) | R28: =IF(ISBLANK(P28),"",IFERROR((VLOOKUP(N28,'Food List'!$C:$H,4,FALSE))*P28,"")) | S28: =IF(ISBLANK(P28),"",IFERROR((VLOOKUP(N28,'Food List'!$C:$H,5,FALSE))*P28,"")) | T28: =IF(ISBLANK(P28),"",IFERROR((VLOOKUP(N28,'Food List'!$C:$H,6,FALSE))*P28,""))
E29: =IF(ISBLANK(D29),"",IFERROR((VLOOKUP(D29,'Food List'!$C:$H,2,FALSE)),"")) | G29: =IF(ISBLANK(F29),"",IFERROR((VLOOKUP(D29,'Food List'!$C:$H,3,FALSE))*F29,"")) | H29: =IF(ISBLANK(F29),"",IFERROR((VLOOKUP(D29,'Food List'!$C:$H,4,FALSE))*F29,"")) | I29: =IF(ISBLANK(F29),"",IFERROR((VLOOKUP(D29,'Food List'!$C:$H,5,FALSE))*F29,"")) | J29: =IF(ISBLANK(F29),"",IFERROR((VLOOKUP(D29,'Food List'!$C:$H,6,FALSE))*F29,"")) | O29: =IF(ISBLANK(N29),"",IFERROR((VLOOKUP(N29,'Food List'!$C:$H,2,FALSE)),"")) | Q29: =IF(ISBLANK(P29),"",IFERROR((VLOOKUP(N29,'Food List'!$C:$H,3,FALSE))*P29,"")) | R29: =IF(ISBLANK(P29),"",IFERROR((VLOOKUP(N29,'Food List'!$C:$H,4,FALSE))*P29,"")) | S29: =IF(ISBLANK(P29),"",IFERROR((VLOOKUP(N29,'Food List'!$C:$H,5,FALSE))*P29,"")) | T29: =IF(ISBLANK(P29),"",IFERROR((VLOOKUP(N29,'Food List'!$C:$H,6,FALSE))*P29,""))
D30: MEAL TOTAL | G30: =IFERROR(SUM(G24:G29),0) -> 404.4 | H30: =IFERROR(SUM(H24:H29),0) -> 43.2 | I30: =IFERROR(SUM(I24:I29),0) -> 51.7 | J30: =IFERROR(SUM(J24:J29),0) -> 2.67 | N30: MEAL TOTAL | Q30: =IFERROR(SUM(Q24:Q29),0) -> 389.5 | R30: =IFERROR(SUM(R24:R29),0) -> 28.55 | S30: =IFERROR(SUM(S24:S29),0) -> 43.9 | T30: =IFERROR(SUM(T24:T29),0) -> 11.05
B32: M4 | D32: Protein Bar | E32: =IF(ISBLANK(D32),"",IFERROR((VLOOKUP(D32,'Food List'!$C:$H,2,FALSE)),"")) -> 1 Bar | F32: 1 | G32: =IF(ISBLANK(F32),"",IFERROR((VLOOKUP(D32,'Food List'!$C:$H,3,FALSE))*F32,"")) -> 200 | H32: =IF(ISBLANK(F32),"",IFERROR((VLOOKUP(D32,'Food List'!$C:$H,4,FALSE))*F32,"")) -> 20 | I32: =IF(ISBLANK(F32),"",IFERROR((VLOOKUP(D32,'Food List'!$C:$H,5,FALSE))*F32,"")) -> 20 | J32: =IF(ISBLANK(F32),"",IFERROR((VLOOKUP(D32,'Food List'!$C:$H,6,FALSE))*F32,"")) -> 5 | L32: M4 | O32: =IF(ISBLANK(N32),"",IFERROR((VLOOKUP(N32,'Food List'!$C:$H,2,FALSE)),"")) | Q32: =IF(ISBLANK(P32),"",IFERROR((VLOOKUP(N32,'Food List'!$C:$H,3,FALSE))*P32,"")) | R32: =IF(ISBLANK(P32),"",IFERROR((VLOOKUP(N32,'Food List'!$C:$H,4,FALSE))*P32,"")) | S32: =IF(ISBLANK(P32),"",IFERROR((VLOOKUP(N32,'Food List'!$C:$H,5,FALSE))*P32,"")) | T32: =IF(ISBLANK(P32),"",IFERROR((VLOOKUP(N32,'Food List'!$C:$H,6,FALSE))*P32,""))
D33: Banana | E33: =IF(ISBLANK(D33),"",IFERROR((VLOOKUP(D33,'Food List'!$C:$H,2,FALSE)),"")) -> 100g | F33: 1.3 | G33: =IF(ISBLANK(F33),"",IFERROR((VLOOKUP(D33,'Food List'!$C:$H,3,FALSE))*F33,"")) -> 111.8 | H33: =IF(ISBLANK(F33),"",IFERROR((VLOOKUP(D33,'Food List'!$C:$H,4,FALSE))*F33,"")) -> 1.56 | I33: =IF(ISBLANK(F33),"",IFERROR((VLOOKUP(D33,'Food List'!$C:$H,5,FALSE))*F33,"")) -> 26 | J33: =IF(ISBLANK(F33),"",IFERROR((VLOOKUP(D33,'Food List'!$C:$H,6,FALSE))*F33,"")) -> 0.13 | O33: =IF(ISBLANK(N33),"",IFERROR((VLOOKUP(N33,'Food List'!$C:$H,2,FALSE)),"")) | Q33: =IF(ISBLANK(P33),"",IFERROR((VLOOKUP(N33,'Food List'!$C:$H,3,FALSE))*P33,"")) | R33: =IF(ISBLANK(P33),"",IFERROR((VLOOKUP(N33,'Food List'!$C:$H,4,FALSE))*P33,"")) | S33: =IF(ISBLANK(P33),"",IFERROR((VLOOKUP(N33,'Food List'!$C:$H,5,FALSE))*P33,"")) | T33: =IF(ISBLANK(P33),"",IFERROR((VLOOKUP(N33,'Food List'!$C:$H,6,FALSE))*P33,""))
E34: =IF(ISBLANK(D34),"",IFERROR((VLOOKUP(D34,'Food List'!$C:$H,2,FALSE)),"")) | G34: =IF(ISBLANK(F34),"",IFERROR((VLOOKUP(D34,'Food List'!$C:$H,3,FALSE))*F34,"")) | H34: =IF(ISBLANK(F34),"",IFERROR((VLOOKUP(D34,'Food List'!$C:$H,4,FALSE))*F34,"")) | I34: =IF(ISBLANK(F34),"",IFERROR((VLOOKUP(D34,'Food List'!$C:$H,5,FALSE))*F34,"")) | J34: =IF(ISBLANK(F34),"",IFERROR((VLOOKUP(D34,'Food List'!$C:$H,6,FALSE))*F34,"")) | O34: =IF(ISBLANK(N34),"",IFERROR((VLOOKUP(N34,'Food List'!$C:$H,2,FALSE)),"")) | Q34: =IF(ISBLANK(P34),"",IFERROR((VLOOKUP(N34,'Food List'!$C:$H,3,FALSE))*P34,"")) | R34: =IF(ISBLANK(P34),"",IFERROR((VLOOKUP(N34,'Food List'!$C:$H,4,FALSE))*P34,"")) | S34: =IF(ISBLANK(P34),"",IFERROR((VLOOKUP(N34,'Food List'!$C:$H,5,FALSE))*P34,"")) | T34: =IF(ISBLANK(P34),"",IFERROR((VLOOKUP(N34,'Food List'!$C:$H,6,FALSE))*P34,""))
E35: =IF(ISBLANK(D35),"",IFERROR((VLOOKUP(D35,'Food List'!$C:$H,2,FALSE)),"")) | G35: =IF(ISBLANK(F35),"",IFERROR((VLOOKUP(D35,'Food List'!$C:$H,3,FALSE))*F35,"")) | H35: =IF(ISBLANK(F35),"",IFERROR((VLOOKUP(D35,'Food List'!$C:$H,4,FALSE))*F35,"")) | I35: =IF(ISBLANK(F35),"",IFERROR((VLOOKUP(D35,'Food List'!$C:$H,5,FALSE))*F35,"")) | J35: =IF(ISBLANK(F35),"",IFERROR((VLOOKUP(D35,'Food List'!$C:$H,6,FALSE))*F35,"")) | O35: =IF(ISBLANK(N35),"",IFERROR((VLOOKUP(N35,'Food List'!$C:$H,2,FALSE)),"")) | Q35: =IF(ISBLANK(P35),"",IFERROR((VLOOKUP(N35,'Food List'!$C:$H,3,FALSE))*P35,"")) | R35: =IF(ISBLANK(P35),"",IFERROR((VLOOKUP(N35,'Food List'!$C:$H,4,FALSE))*P35,"")) | S35: =IF(ISBLANK(P35),"",IFERROR((VLOOKUP(N35,'Food List'!$C:$H,5,FALSE))*P35,"")) | T35: =IF(ISBLANK(P35),"",IFERROR((VLOOKUP(N35,'Food List'!$C:$H,6,FALSE))*P35,""))
E36: =IF(ISBLANK(D36),"",IFERROR((VLOOKUP(D36,'Food List'!$C:$H,2,FALSE)),"")) | G36: =IF(ISBLANK(F36),"",IFERROR((VLOOKUP(D36,'Food List'!$C:$H,3,FALSE))*F36,"")) | H36: =IF(ISBLANK(F36),"",IFERROR((VLOOKUP(D36,'Food List'!$C:$H,4,FALSE))*F36,"")) | I36: =IF(ISBLANK(F36),"",IFERROR((VLOOKUP(D36,'Food List'!$C:$H,5,FALSE))*F36,"")) | J36: =IF(ISBLANK(F36),"",IFERROR((VLOOKUP(D36,'Food List'!$C:$H,6,FALSE))*F36,"")) | O36: =IF(ISBLANK(N36),"",IFERROR((VLOOKUP(N36,'Food List'!$C:$H,2,FALSE)),"")) | Q36: =IF(ISBLANK(P36),"",IFERROR((VLOOKUP(N36,'Food List'!$C:$H,3,FALSE))*P36,"")) | R36: =IF(ISBLANK(P36),"",IFERROR((VLOOKUP(N36,'Food List'!$C:$H,4,FALSE))*P36,"")) | S36: =IF(ISBLANK(P36),"",IFERROR((VLOOKUP(N36,'Food List'!$C:$H,5,FALSE))*P36,"")) | T36: =IF(ISBLANK(P36),"",IFERROR((VLOOKUP(N36,'Food List'!$C:$H,6,FALSE))*P36,""))
E37: =IF(ISBLANK(D37),"",IFERROR((VLOOKUP(D37,'Food List'!$C:$H,2,FALSE)),"")) | G37: =IF(ISBLANK(F37),"",IFERROR((VLOOKUP(D37,'Food List'!$C:$H,3,FALSE))*F37,"")) | H37: =IF(ISBLANK(F37),"",IFERROR((VLOOKUP(D37,'Food List'!$C:$H,4,FALSE))*F37,"")) | I37: =IF(ISBLANK(F37),"",IFERROR((VLOOKUP(D37,'Food List'!$C:$H,5,FALSE))*F37,"")) | J37: =IF(ISBLANK(F37),"",IFERROR((VLOOKUP(D37,'Food List'!$C:$H,6,FALSE))*F37,"")) | O37: =IF(ISBLANK(N37),"",IFERROR((VLOOKUP(N37,'Food List'!$C:$H,2,FALSE)),"")) | Q37: =IF(ISBLANK(P37),"",IFERROR((VLOOKUP(N37,'Food List'!$C:$H,3,FALSE))*P37,"")) | R37: =IF(ISBLANK(P37),"",IFERROR((VLOOKUP(N37,'Food List'!$C:$H,4,FALSE))*P37,"")) | S37: =IF(ISBLANK(P37),"",IFERROR((VLOOKUP(N37,'Food List'!$C:$H,5,FALSE))*P37,"")) | T37: =IF(ISBLANK(P37),"",IFERROR((VLOOKUP(N37,'Food List'!$C:$H,6,FALSE))*P37,""))
D38: MEAL TOTAL | G38: =IFERROR(SUM(G32:G37),0) -> 311.8 | H38: =IFERROR(SUM(H32:H37),0) -> 21.56 | I38: =IFERROR(SUM(I32:I37),0) -> 46 | J38: =IFERROR(SUM(J32:J37),0) -> 5.13 | N38: MEAL TOTAL | Q38: =IFERROR(SUM(Q32:Q37),0) -> 0 | R38: =IFERROR(SUM(R32:R37),0) -> 0 | S38: =IFERROR(SUM(S32:S37),0) -> 0 | T38: =IFERROR(SUM(T32:T37),0) -> 0
B40: M5 | E40: =IF(ISBLANK(D40),"",IFERROR((VLOOKUP(D40,'Food List'!$C:$H,2,FALSE)),"")) | G40: =IF(ISBLANK(F40),"",IFERROR((VLOOKUP(D40,'Food List'!$C:$H,3,FALSE))*F40,"")) | H40: =IF(ISBLANK(F40),"",IFERROR((VLOOKUP(D40,'Food List'!$C:$H,4,FALSE))*F40,"")) | I40: =IF(ISBLANK(F40),"",IFERROR((VLOOKUP(D40,'Food List'!$C:$H,5,FALSE))*F40,"")) | J40: =IF(ISBLANK(F40),"",IFERROR((VLOOKUP(D40,'Food List'!$C:$H,6,FALSE))*F40,"")) | L40: M5 | O40: =IF(ISBLANK(N40),"",IFERROR((VLOOKUP(N40,'Food List'!$C:$H,2,FALSE)),"")) | Q40: =IF(ISBLANK(P40),"",IFERROR((VLOOKUP(N40,'Food List'!$C:$H,3,FALSE))*P40,"")) | R40: =IF(ISBLANK(P40),"",IFERROR((VLOOKUP(N40,'Food List'!$C:$H,4,FALSE))*P40,"")) | S40: =IF(ISBLANK(P40),"",IFERROR((VLOOKUP(N40,'Food List'!$C:$H,5,FALSE))*P40,"")) | T40: =IF(ISBLANK(P40),"",IFERROR((VLOOKUP(N40,'Food List'!$C:$H,6,FALSE))*P40,""))
E41: =IF(ISBLANK(D41),"",IFERROR((VLOOKUP(D41,'Food List'!$C:$H,2,FALSE)),"")) | G41: =IF(ISBLANK(F41),"",IFERROR((VLOOKUP(D41,'Food List'!$C:$H,3,FALSE))*F41,"")) | H41: =IF(ISBLANK(F41),"",IFERROR((VLOOKUP(D41,'Food List'!$C:$H,4,FALSE))*F41,"")) | I41: =IF(ISBLANK(F41),"",IFERROR((VLOOKUP(D41,'Food List'!$C:$H,5,FALSE))*F41,"")) | J41: =IF(ISBLANK(F41),"",IFERROR((VLOOKUP(D41,'Food List'!$C:$H,6,FALSE))*F41,"")) | O41: =IF(ISBLANK(N41),"",IFERROR((VLOOKUP(N41,'Food List'!$C:$H,2,FALSE)),"")) | Q41: =IF(ISBLANK(P41),"",IFERROR((VLOOKUP(N41,'Food List'!$C:$H,3,FALSE))*P41,"")) | R41: =IF(ISBLANK(P41),"",IFERROR((VLOOKUP(N41,'Food List'!$C:$H,4,FALSE))*P41,"")) | S41: =IF(ISBLANK(P41),"",IFERROR((VLOOKUP(N41,'Food List'!$C:$H,5,FALSE))*P41,"")) | T41: =IF(ISBLANK(P41),"",IFERROR((VLOOKUP(N41,'Food List'!$C:$H,6,FALSE))*P41,""))
E42: =IF(ISBLANK(D42),"",IFERROR((VLOOKUP(D42,'Food List'!$C:$H,2,FALSE)),"")) | G42: =IF(ISBLANK(F42),"",IFERROR((VLOOKUP(D42,'Food List'!$C:$H,3,FALSE))*F42,"")) | H42: =IF(ISBLANK(F42),"",IFERROR((VLOOKUP(D42,'Food List'!$C:$H,4,FALSE))*F42,"")) | I42: =IF(ISBLANK(F42),"",IFERROR((VLOOKUP(D42,'Food List'!$C:$H,5,FALSE))*F42,"")) | J42: =IF(ISBLANK(F42),"",IFERROR((VLOOKUP(D42,'Food List'!$C:$H,6,FALSE))*F42,"")) | O42: =IF(ISBLANK(N42),"",IFERROR((VLOOKUP(N42,'Food List'!$C:$H,2,FALSE)),"")) | Q42: =IF(ISBLANK(P42),"",IFERROR((VLOOKUP(N42,'Food List'!$C:$H,3,FALSE))*P42,"")) | R42: =IF(ISBLANK(P42),"",IFERROR((VLOOKUP(N42,'Food List'!$C:$H,4,FALSE))*P42,"")) | S42: =IF(ISBLANK(P42),"",IFERROR((VLOOKUP(N42,'Food List'!$C:$H,5,FALSE))*P42,"")) | T42: =IF(ISBLANK(P42),"",IFERROR((VLOOKUP(N42,'Food List'!$C:$H,6,FALSE))*P42,""))
E43: =IF(ISBLANK(D43),"",IFERROR((VLOOKUP(D43,'Food List'!$C:$H,2,FALSE)),"")) | G43: =IF(ISBLANK(F43),"",IFERROR((VLOOKUP(D43,'Food List'!$C:$H,3,FALSE))*F43,"")) | H43: =IF(ISBLANK(F43),"",IFERROR((VLOOKUP(D43,'Food List'!$C:$H,4,FALSE))*F43,"")) | I43: =IF(ISBLANK(F43),"",IFERROR((VLOOKUP(D43,'Food List'!$C:$H,5,FALSE))*F43,"")) | J43: =IF(ISBLANK(F43),"",IFERROR((VLOOKUP(D43,'Food List'!$C:$H,6,FALSE))*F43,"")) | O43: =IF(ISBLANK(N43),"",IFERROR((VLOOKUP(N43,'Food List'!$C:$H,2,FALSE)),"")) | Q43: =IF(ISBLANK(P43),"",IFERROR((VLOOKUP(N43,'Food List'!$C:$H,3,FALSE))*P43,"")) | R43: =IF(ISBLANK(P43),"",IFERROR((VLOOKUP(N43,'Food List'!$C:$H,4,FALSE))*P43,"")) | S43: =IF(ISBLANK(P43),"",IFERROR((VLOOKUP(N43,'Food List'!$C:$H,5,FALSE))*P43,"")) | T43: =IF(ISBLANK(P43),"",IFERROR((VLOOKUP(N43,'Food List'!$C:$H,6,FALSE))*P43,""))
E44: =IF(ISBLANK(D44),"",IFERROR((VLOOKUP(D44,'Food List'!$C:$H,2,FALSE)),"")) | G44: =IF(ISBLANK(F44),"",IFERROR((VLOOKUP(D44,'Food List'!$C:$H,3,FALSE))*F44,"")) | H44: =IF(ISBLANK(F44),"",IFERROR((VLOOKUP(D44,'Food List'!$C:$H,4,FALSE))*F44,"")) | I44: =IF(ISBLANK(F44),"",IFERROR((VLOOKUP(D44,'Food List'!$C:$H,5,FALSE))*F44,"")) | J44: =IF(ISBLANK(F44),"",IFERROR((VLOOKUP(D44,'Food List'!$C:$H,6,FALSE))*F44,"")) | O44: =IF(ISBLANK(N44),"",IFERROR((VLOOKUP(N44,'Food List'!$C:$H,2,FALSE)),"")) | Q44: =IF(ISBLANK(P44),"",IFERROR((VLOOKUP(N44,'Food List'!$C:$H,3,FALSE))*P44,"")) | R44: =IF(ISBLANK(P44),"",IFERROR((VLOOKUP(N44,'Food List'!$C:$H,4,FALSE))*P44,"")) | S44: =IF(ISBLANK(P44),"",IFERROR((VLOOKUP(N44,'Food List'!$C:$H,5,FALSE))*P44,"")) | T44: =IF(ISBLANK(P44),"",IFERROR((VLOOKUP(N44,'Food List'!$C:$H,6,FALSE))*P44,""))
E45: =IF(ISBLANK(D45),"",IFERROR((VLOOKUP(D45,'Food List'!$C:$H,2,FALSE)),"")) | G45: =IF(ISBLANK(F45),"",IFERROR((VLOOKUP(D45,'Food List'!$C:$H,3,FALSE))*F45,"")) | H45: =IF(ISBLANK(F45),"",IFERROR((VLOOKUP(D45,'Food List'!$C:$H,4,FALSE))*F45,"")) | I45: =IF(ISBLANK(F45),"",IFERROR((VLOOKUP(D45,'Food List'!$C:$H,5,FALSE))*F45,"")) | J45: =IF(ISBLANK(F45),"",IFERROR((VLOOKUP(D45,'Food List'!$C:$H,6,FALSE))*F45,"")) | O45: =IF(ISBLANK(N45),"",IFERROR((VLOOKUP(N45,'Food List'!$C:$H,2,FALSE)),"")) | Q45: =IF(ISBLANK(P45),"",IFERROR((VLOOKUP(N45,'Food List'!$C:$H,3,FALSE))*P45,"")) | R45: =IF(ISBLANK(P45),"",IFERROR((VLOOKUP(N45,'Food List'!$C:$H,4,FALSE))*P45,"")) | S45: =IF(ISBLANK(P45),"",IFERROR((VLOOKUP(N45,'Food List'!$C:$H,5,FALSE))*P45,"")) | T45: =IF(ISBLANK(P45),"",IFERROR((VLOOKUP(N45,'Food List'!$C:$H,6,FALSE))*P45,""))
...

Sheet Meal Plan - 7 Day
B1: MAHON PERFORMANCE
E2: DAY | F2: CALS | G2: PRO | H2: CHO | I2: FAT
E3: MON | F3: =G59 -> 1469.1 | G3: =H59 -> 134.02 | H3: =I59 -> 156.35 | I3: =J59 -> 34.05
E4: TUES | F4: =Q59 -> 1135 | G4: =R59 -> 90.05 | H4: =S59 -> 93.6 | I4: =T59 -> 44.35
E5: WED | F5: =AA59 -> 922.1 | G5: =AB59 -> 110.12 | H5: =AC59 -> 93.8 | I5: =AD59 -> 10.8
E6: THURS | F6: =AK59 -> 0 | G6: =AL59 -> 0 | H6: =AM59 -> 0 | I6: =AN59 -> 0
E7: FRI | F7: =AU59 -> 0 | G7: =AV59 -> 0 | H7: =AW59 -> 0 | I7: =AX59 -> 0
E8: SAT | F8: =BE59 -> 0 | G8: =BF59 -> 0 | H8: =BG59 -> 0 | I8: =BH59 -> 0
E9: SUN | F9: =BO59 -> 0 | G9: =BP59 -> 0 | H9: =BQ59 -> 0 | I9: =BR59 -> 0
B11: MONDAY | L11: TUESDAY | V11: WEDNESDAY | AF11: THURSDAY | AP11: FRIDAY | AZ11: SATURDAY | BJ11: SUNDAY
B12: MEAL NO. | D12: FOOD | E12: PORTION | F12: NO. OF PORTIONS | G12: CALS | H12: PRO | I12: CHO | J12: FAT | L12: MEAL NO. | N12: FOOD | O12: PORTION | P12: NO. OF PORTIONS | Q12: CALS | R12: PRO | S12: CHO | T12: FAT | V12: MEAL NO. | X12: FOOD | Y12: PORTION | Z12: NO. OF PORTIONS | AA12: CALS | AB12: PRO | AC12: CHO | AD12: FAT | AF12: MEAL NO. | AH12: FOOD | AI12: PORTION | AJ12: NO. OF PORTIONS | AK12: CALS | AL12: PRO | AM12: CHO | AN12: FAT | AP12: MEAL NO. | AR12: FOOD | AS12: PORTION | AT12: NO. OF PORTIONS | AU12: CALS | AV12: PRO | AW12: CHO | AX12: FAT | AZ12: MEAL NO. | BB12: FOOD | BC12: PORTION | BD12: NO. OF PORTIONS | BE12: CALS | BF12: PRO | BG12: CHO | BH12: FAT | BJ12: MEAL NO. | BL12: FOOD | BM12: PORTION | BN12: NO. OF PORTIONS | BO12: CALS | BP12: PRO | BQ12: CHO | BR12: FAT
B13: M1 | D13: Greek Yoghurt (0%) | E13: =IF(ISBLANK(D13),"",IFERROR((VLOOKUP(D13,'Food List'!$C:$H,2,FALSE)),"")) -> 100g | F13: 3 | G13: =IF(ISBLANK(F13),"",IFERROR((VLOOKUP(D13,'Food List'!$C:$H,3,FALSE))*F13,"")) -> 174 | H13: =IF(ISBLANK(F13),"",IFERROR((VLOOKUP(D13,'Food List'!$C:$H,4,FALSE))*F13,"")) -> 31.8 | I13: =IF(ISBLANK(F13),"",IFERROR((VLOOKUP(D13,'Food List'!$C:$H,5,FALSE))*F13,"")) -> 11.7 | J13: =IF(ISBLANK(F13),"",IFERROR((VLOOKUP(D13,'Food List'!$C:$H,6,FALSE))*F13,"")) -> 0 | L13: M1 | N13: Eggs Whole | O13: =IF(ISBLANK(N13),"",IFERROR((VLOOKUP(N13,'Food List'!$C:$H,2,FALSE)),"")) -> 1 egg | P13: 2 | Q13: =IF(ISBLANK(P13),"",IFERROR((VLOOKUP(N13,'Food List'!$C:$H,3,FALSE))*P13,"")) -> 144 | R13: =IF(ISBLANK(P13),"",IFERROR((VLOOKUP(N13,'Food List'!$C:$H,4,FALSE))*P13,"")) -> 12 | S13: =IF(ISBLANK(P13),"",IFERROR((VLOOKUP(N13,'Food List'!$C:$H,5,FALSE))*P13,"")) -> 0.8 | T13: =IF(ISBLANK(P13),"",IFERROR((VLOOKUP(N13,'Food List'!$C:$H,6,FALSE))*P13,"")) -> 9.6 | V13: M1 | X13: Eggs Whole | Y13: =IF(ISBLANK(X13),"",IFERROR((VLOOKUP(X13,'Food List'!$C:$H,2,FALSE)),"")) -> 1 egg | Z13: 1 | AA13: =IF(ISBLANK(Z13),"",IFERROR((VLOOKUP(X13,'Food List'!$C:$H,3,FALSE))*Z13,"")) -> 72 | AB13: =IF(ISBLANK(Z13),"",IFERROR((VLOOKUP(X13,'Food List'!$C:$H,4,FALSE))*Z13,"")) -> 6 | AC13: =IF(ISBLANK(Z13),"",IFERROR((VLOOKUP(X13,'Food List'!$C:$H,5,FALSE))*Z13,"")) -> 0.4 | AD13: =IF(ISBLANK(Z13),"",IFERROR((VLOOKUP(X13,'Food List'!$C:$H,6,FALSE))*Z13,"")) -> 4.8 | AF13: M1 | AI13: =IF(ISBLANK(AH13),"",IFERROR((VLOOKUP(AH13,'Food List'!$C:$H,2,FALSE)),"")) | AK13: =IF(ISBLANK(AJ13),"",IFERROR((VLOOKUP(AH13,'Food List'!$C:$H,3,FALSE))*AJ13,"")) | AL13: =IF(ISBLANK(AJ13),"",IFERROR((VLOOKUP(AH13,'Food List'!$C:$H,4,FALSE))*AJ13,"")) | AM13: =IF(ISBLANK(AJ13),"",IFERROR((VLOOKUP(AH13,'Food List'!$C:$H,5,FALSE))*AJ13,"")) | AN13: =IF(ISBLANK(AJ13),"",IFERROR((VLOOKUP(AH13,'Food List'!$C:$H,6,FALSE))*AJ13,"")) | AP13: M1 | AS13: =IF(ISBLANK(AR13),"",IFERROR((VLOOKUP(AR13,'Food List'!$C:$H,2,FALSE)),"")) | AU13: =IF(ISBLANK(AT13),"",IFERROR((VLOOKUP(AR13,'Food List'!$C:$H,3,FALSE))*AT13,"")) | AV13: =IF(ISBLANK(AT13),"",IFERROR((VLOOKUP(AR13,'Food List'!$C:$H,4,FALSE))*AT13,"")) | AW13: =IF(ISBLANK(AT13),"",IFERROR((VLOOKUP(AR13,'Food List'!$C:$H,5,FALSE))*AT13,"")) | AX13: =IF(ISBLANK(AT13),"",IFERROR((VLOOKUP(AR13,'Food List'!$C:$H,6,FALSE))*AT13,"")) | AZ13: M1 | BC13: =IF(ISBLANK(BB13),"",IFERROR((VLOOKUP(BB13,'Food List'!$C:$H,2,FALSE)),"")) | BE13: =IF(ISBLANK(BD13),"",IFERROR((VLOOKUP(BB13,'Food List'!$C:$H,3,FALSE))*BD13,"")) | BF13: =IF(ISBLANK(BD13),"",IFERROR((VLOOKUP(BB13,'Food List'!$C:$H,4,FALSE))*BD13,"")) | BG13: =IF(ISBLANK(BD13),"",IFERROR((VLOOKUP(BB13,'Food List'!$C:$H,5,FALSE))*BD13,"")) | BH13: =IF(ISBLANK(BD13),"",IFERROR((VLOOKUP(BB13,'Food List'!$C:$H,6,FALSE))*BD13,"")) | BJ13: M1 | BM13: =IF(ISBLANK(BL13),"",IFERROR((VLOOKUP(BL13,'Food List'!$C:$H,2,FALSE)),"")) | BO13: =IF(ISBLANK(BN13),"",IFERROR((VLOOKUP(BL13,'Food List'!$C:$H,3,FALSE))*BN13,"")) | BP13: =IF(ISBLANK(BN13),"",IFERROR((VLOOKUP(BL13,'Food List'!$C:$H,4,FALSE))*BN13,"")) | BQ13: =IF(ISBLANK(BN13),"",IFERROR((VLOOKUP(BL13,'Food List'!$C:$H,5,FALSE))*BN13,"")) | BR13: =IF(ISBLANK(BN13),"",IFERROR((VLOOKUP(BL13,'Food List'!$C:$H,6,FALSE))*BN13,""))
D14: Raspberries | E14: =IF(ISBLANK(D14),"",IFERROR((VLOOKUP(D14,'Food List'!$C:$H,2,FALSE)),"")) -> 100g | F14: 2 | G14: =IF(ISBLANK(F14),"",IFERROR((VLOOKUP(D14,'Food List'!$C:$H,3,FALSE))*F14,"")) -> 54 | H14: =IF(ISBLANK(F14),"",IFERROR((VLOOKUP(D14,'Food List'!$C:$H,4,FALSE))*F14,"")) -> 2.8 | I14: =IF(ISBLANK(F14),"",IFERROR((VLOOKUP(D14,'Food List'!$C:$H,5,FALSE))*F14,"")) -> 9.2 | J14: =IF(ISBLANK(F14),"",IFERROR((VLOOKUP(D14,'Food List'!$C:$H,6,FALSE))*F14,"")) -> 0.6 | N14: White Sourdough Bread | O14: =IF(ISBLANK(N14),"",IFERROR((VLOOKUP(N14,'Food List'!$C:$H,2,FALSE)),"")) -> 100g | P14: 0.5 | Q14: =IF(ISBLANK(P14),"",IFERROR((VLOOKUP(N14,'Food List'!$C:$H,3,FALSE))*P14,"")) -> 139.5 | R14: =IF(ISBLANK(P14),"",IFERROR((VLOOKUP(N14,'Food List'!$C:$H,4,FALSE))*P14,"")) -> 5.9 | S14: =IF(ISBLANK(P14),"",IFERROR((VLOOKUP(N14,'Food List'!$C:$H,5,FALSE))*P14,"")) -> 27 | T14: =IF(ISBLANK(P14),"",IFERROR((VLOOKUP(N14,'Food List'!$C:$H,6,FALSE))*P14,"")) -> 0.9 | X14: Turkey Rasher | Y14: =IF(ISBLANK(X14),"",IFERROR((VLOOKUP(X14,'Food List'!$C:$H,2,FALSE)),"")) -> 1 rasher | Z14: 2 | AA14: =IF(ISBLANK(Z14),"",IFERROR((VLOOKUP(X14,'Food List'!$C:$H,3,FALSE))*Z14,"")) -> 58 | AB14: =IF(ISBLANK(Z14),"",IFERROR((VLOOKUP(X14,'Food List'!$C:$H,4,FALSE))*Z14,"")) -> 10.2 | AC14: =IF(ISBLANK(Z14),"",IFERROR((VLOOKUP(X14,'Food List'!$C:$H,5,FALSE))*Z14,"")) -> 1 | AD14: =IF(ISBLANK(Z14),"",IFERROR((VLOOKUP(X14,'Food List'!$C:$H,6,FALSE))*Z14,"")) -> 1.4 | AI14: =IF(ISBLANK(AH14),"",IFERROR((VLOOKUP(AH14,'Food List'!$C:$H,2,FALSE)),"")) | AK14: =IF(ISBLANK(AJ14),"",IFERROR((VLOOKUP(AH14,'Food List'!$C:$H,3,FALSE))*AJ14,"")) | AL14: =IF(ISBLANK(AJ14),"",IFERROR((VLOOKUP(AH14,'Food List'!$C:$H,4,FALSE))*AJ14,"")) | AM14: =IF(ISBLANK(AJ14),"",IFERROR((VLOOKUP(AH14,'Food List'!$C:$H,5,FALSE))*AJ14,"")) | AN14: =IF(ISBLANK(AJ14),"",IFERROR((VLOOKUP(AH14,'Food List'!$C:$H,6,FALSE))*AJ14,"")) | AS14: =IF(ISBLANK(AR14),"",IFERROR((VLOOKUP(AR14,'Food List'!$C:$H,2,FALSE)),"")) | AU14: =IF(ISBLANK(AT14),"",IFERROR((VLOOKUP(AR14,'Food List'!$C:$H,3,FALSE))*AT14,"")) | AV14: =IF(ISBLANK(AT14),"",IFERROR((VLOOKUP(AR14,'Food List'!$C:$H,4,FALSE))*AT14,"")) | AW14: =IF(ISBLANK(AT14),"",IFERROR((VLOOKUP(AR14,'Food List'!$C:$H,5,FALSE))*AT14,"")) | AX14: =IF(ISBLANK(AT14),"",IFERROR((VLOOKUP(AR14,'Food List'!$C:$H,6,FALSE))*AT14,"")) | BC14: =IF(ISBLANK(BB14),"",IFERROR((VLOOKUP(BB14,'Food List'!$C:$H,2,FALSE)),"")) | BE14: =IF(ISBLANK(BD14),"",IFERROR((VLOOKUP(BB14,'Food List'!$C:$H,3,FALSE))*BD14,"")) | BF14: =IF(ISBLANK(BD14),"",IFERROR((VLOOKUP(BB14,'Food List'!$C:$H,4,FALSE))*BD14,"")) | BG14: =IF(ISBLANK(BD14),"",IFERROR((VLOOKUP(BB14,'Food List'!$C:$H,5,FALSE))*BD14,"")) | BH14: =IF(ISBLANK(BD14),"",IFERROR((VLOOKUP(BB14,'Food List'!$C:$H,6,FALSE))*BD14,"")) | BM14: =IF(ISBLANK(BL14),"",IFERROR((VLOOKUP(BL14,'Food List'!$C:$H,2,FALSE)),"")) | BO14: =IF(ISBLANK(BN14),"",IFERROR((VLOOKUP(BL14,'Food List'!$C:$H,3,FALSE))*BN14,"")) | BP14: =IF(ISBLANK(BN14),"",IFERROR((VLOOKUP(BL14,'Food List'!$C:$H,4,FALSE))*BN14,"")) | BQ14: =IF(ISBLANK(BN14),"",IFERROR((VLOOKUP(BL14,'Food List'!$C:$H,5,FALSE))*BN14,"")) | BR14: =IF(ISBLANK(BN14),"",IFERROR((VLOOKUP(BL14,'Food List'!$C:$H,6,FALSE))*BN14,""))
